Workbook
Name AÑO: '1 ahu'!$D:$D
Name AÑO: '10 sv'!$D:$D
Name AÑO: '11 usu'!$D:$D
Name AÑO: '12 sm'!$D:$D
Name AÑO: '13 mor'!$D:$D
Name AÑO: '14 LU'!$D:$D
Name AÑO: '2 sa'!$D:$D
Name AÑO: '4 cha'!$D:$D
Name AÑO: '5 LL'!$D:$D
Name AÑO: '7 cus'!$D:$D
Name AÑO: '8 lp'!$D:$D
Name AÑO: '9 cab'!$D:$D
Name AÑO: 'N TRIBUTARIO'!$D:$D
Name AREAKM2: '1 ahu'!$AB:$AB
Name AREAKM2: '10 sv'!$AB:$AB
Name AREAKM2: '11 usu'!$AB:$AB
Name AREAKM2: '12 sm'!$AB:$AB
Name AREAKM2: '13 mor'!$AB:$AB
Name AREAKM2: '14 LU'!$AB:$AB
Name AREAKM2: '2 sa'!$AB:$AB
Name AREAKM2: '4 cha'!$AB:$AB
Name AREAKM2: '5 LL'!$AB:$AB
Name AREAKM2: '7 cus'!$AB:$AB
Name AREAKM2: '8 lp'!$AB:$AB
Name AREAKM2: '9 cab'!$AB:$AB
Name AREAKM2: 'N TRIBUTARIO'!$AA:$AA
Name CODIGO: '1 ahu'!$F:$F
Name CODIGO: '10 sv'!$F:$F
Name CODIGO: '11 usu'!$F:$F
Name CODIGO: '12 sm'!$F:$F
Name CODIGO: '13 mor'!$F:$F
Name CODIGO: '14 LU'!$F:$F
Name CODIGO: '2 sa'!$F:$F
Name CODIGO: '4 cha'!$F:$F
Name CODIGO: '5 LL'!$F:$F
Name CODIGO: '7 cus'!$F:$F
Name CODIGO: '8 lp'!$F:$F
Name CODIGO: '9 cab'!$F:$F
Name CODIGO: 'N TRIBUTARIO'!$F:$F
Name CODNOMZ: '1 ahu'!$AA:$AA
Name CODNOMZ: '10 sv'!$AA:$AA
Name CODNOMZ: '11 usu'!$AA:$AA
Name CODNOMZ: '12 sm'!$AA:$AA
Name CODNOMZ: '13 mor'!$AA:$AA
Name CODNOMZ: '14 LU'!$AA:$AA
Name CODNOMZ: '2 sa'!$AA:$AA
Name CODNOMZ: '4 cha'!$AA:$AA
Name CODNOMZ: '5 LL'!$AA:$AA
Name CODNOMZ: '7 cus'!$AA:$AA
Name CODNOMZ: '8 lp'!$AA:$AA
Name CODNOMZ: '9 cab'!$AA:$AA
Name CODNOMZ: 'N TRIBUTARIO'!$Z:$Z
Name CODZONA: '1 ahu'!$A$1:$AD$13
Name CODZONA: '10 sv'!$A$1:$AD$14
Name CODZONA: '11 usu'!$A$1:$AD$24
Name CODZONA: '12 sm'!$A$1:$AD$21
Name CODZONA: '13 mor'!$A$1:$AD$27
Name CODZONA: '14 LU'!$A$1:$AD$19
Name CODZONA: '2 sa'!$A$1:$AD$14
Name CODZONA: '4 cha'!$A$1:$AD$34

Sheet DEPARTAMENTOS
A1: # DEPTO | B1: DEPARTAMENTO
A2: 1 | B2: AHUACHAPÁN
A3: 2 | B3: SANTA ANA
A4: 3 | B4: SONSONATE
A5: 4 | B5: CHALATENANGO
A6: 5 | B6: LA LIBERTAD
A7: 6 | B7: SAN SALVADOR
A8: 7 | B8: CUSCATLÁN
A9: 8 | B9: LA PAZ
A10: 9 | B10: CABAÑAS
A11: 10 | B11: SAN VICENTE
A12: 11 | B12: USULUTAN
A13: 12 | B13: SAN MIGUEL
... A15: 14 | B15: LA UNION

Sheet municipio
A1: ITEM | B1: MUNICIPIO
A2: 1 | B2: AHUACHAPÁN CENTRO
A3: 2 | B3: AHUACHAPÁN NORTE
A4: 3 | B4: AHUACHAPÁN SUR
A5: 4 | B5: SANTA ANA CENTRO
A6: 5 | B6: SANTA ANA ESTE
A7: 6 | B7: SANTA ANA NORTE
A8: 7 | B8: SANTA ANA OESTE
A9: 8 | B9: SONSONATE CENTRO
A10: 9 | B10: SONSONATE ESTE
A11: 10 | B11: SONSONATE NORTE
A12: 11 | B12: SONSONATE OESTE
A13: 12 | B13: CHALATENANGO CENTRO
... A45: 44 | B45: LA UNIÓN SUR

Sheet DISTRITOS
A1: # DISTRITO | B1: DISTRITOS
A2: 1 | B2: AHUACHAPÁN
A3: 2 | B3: APANECA
A4: 3 | B4: CONCEPCIÓN DE ATACO
A5: 4 | B5: TACUBA
A6: 5 | B6: GUAYMANGO
A7: 6 | B7: JUJUTLA
A8: 7 | B8: SAN FRANCISCO MENÉNDEZ
A9: 8 | B9: SAN PEDRO PUXTLA
A10: 9 | B10: ATIQUIZAYA
A11: 10 | B11: EL REFUGIO
A12: 11 | B12: SAN LORENZO
A13: 12 | B13: TURÍN
... A263: 262 | B263: YUCUAIQUÍN

Sheet UNIONDEPTO
A1: No. | B1: ='N TRIBUTARIO'!M1 -> CENTRO | C1: ='N TRIBUTARIO'!N1 -> COSTA | D1: ='N TRIBUTARIO'!O1 -> ESTE | E1: ='N TRIBUTARIO'!P1 -> NORTE | F1: ='N TRIBUTARIO'!Q1 -> OESTE | G1: ='N TRIBUTARIO'!R1 -> SUR | H1: =SUM(H2:H45) -> 262 | J1: Distritos internos | K1: Area (km²) | L1: Poblacion | M1: Densidad (Hab/Km²)
A2: =municipio!A2 -> 1 | B2: ='1 ahu'!N14 -> 4 | C2: ='1 ahu'!O14 -> 0 | D2: ='1 ahu'!P14 -> 0 | F2: ='1 ahu'!R14 -> 0 | H2: =SUM(B2:G4) -> 12 | I2: =municipio!B2 -> AHUACHAPÁN CENTRO | J2: ='1 ahu'!K16 -> AHUACHAPAN, APANECA, CONCEPCION DE ATACO, TACUBA | K2: 501.01 | L2: 237889 | M2: 474.82
A3: =municipio!A3 -> 2 | E3: ='1 ahu'!Q14 -> 4 | I3: =municipio!B3 -> AHUACHAPÁN NORTE | J3: ='1 ahu'!K17 -> ATIQUIZAYA, EL REFUGIO, SAN LORENZO, TURIN | K3: 146.89 | L3: 61720 | M3: 420.18
A4: =municipio!A4 -> 3 | G4: ='1 ahu'!S14 -> 4 | I4: =municipio!B4 -> AHUACHAPÁN SUR | J4: ='1 ahu'!K18 -> GUAYMANGO, JUJUTLA, SAN FRANCISCO MENENDEZ, SAN PEDRO PUXTLA | K4: 591.43 | L4: 102457 | M4: 173.24
A5: =municipio!A5 -> 4 | B5: ='2 sa'!N15 -> 1 | C5: ='2 sa'!O15 -> 0 | G5: ='2 sa'!S15 -> 0 | H5: =SUM(B5:G8) -> 13 | I5: =municipio!B5 -> SANTA ANA CENTRO | J5: ='2 sa'!K18 -> SANTA ANA | K5: 400.05 | L5: 264091 | M5: 660.14
A6: =municipio!A6 -> 5 | D6: ='2 sa'!P15 -> 2 | I6: =municipio!B6 -> SANTA ANA ESTE | J6: ='2 sa'!K19 -> COATEPEQUE, EL CONGO | K6: 218.28 | L6: 64061 | M6: 293.48
A7: =municipio!A7 -> 6 | E7: ='2 sa'!Q15 -> 4 | I7: =municipio!B7 -> SANTA ANA NORTE | J7: ='2 sa'!K20 -> MASAHUAT, METAPAN, SANTA ROSA GUACHIPILIN, TEXISTEPEQUE | K7: 956.97 | L7: 91108 | M7: 95.2
A8: =municipio!A8 -> 7 | F8: ='2 sa'!R15 -> 6 | I8: =municipio!B8 -> SANTA ANA OESTE | J8: ='2 sa'!K21 -> CANDELARIA DE LA FRONTERA, CHALCHUAPA, EL PORVENIR, SAN ANTONIO PAJONAL, SAN SEBASTIAN SALITRILLO, SANTIAGO DE LA FRONTERA | K8: 447.87 | L8: 172035 | M8: 384.12
A9: =municipio!A9 -> 8 | B9: ='3 son '!N18 -> 5 | C9: ='3 son '!O18 -> 0 | G9: ='3 son '!S18 -> 0 | H9: =SUM(B9:G12) -> 16 | I9: =municipio!B9 -> SONSONATE CENTRO | J9: ='3 son '!K19 -> NAHULINGO, SAN ANTONIO DEL MONTE, SANTO DOMINGO DE GUZMAN, SONSONATE, SONZACATE | K9: 329.38 | L9: 140920 | M9: 427.83
A10: =municipio!A10 -> 9 | D10: ='3 son '!P18 -> 6 | I10: =municipio!B10 -> SONSONATE ESTE | J10: ='3 son '!K20 -> ARMENIA, CALUCO, CUISNAHUAT, SANTA ISABEL ISHUATAN, IZALCO, SAN JULIAN | K10: 542.89 | L10: 160035 | M10: 294.78
A11: =municipio!A11 -> 10 | E11: ='3 son '!Q18 -> 4 | I11: =municipio!B11 -> SONSONATE NORTE | J11: ='3 son '!K21 -> JUAYUA, NAHUIZALCO, SALCOATITAN, SANTA CATARINA MASAHUAT | K11: 186.91 | L11: 89106 | M11: 476.73
A12: =municipio!A12 -> 11 | F12: ='3 son '!R18 -> 1 | I12: =municipio!B12 -> SONSONATE OESTE | J12: ='3 son '!K22 -> ACAJUTLA | K12: 166.59 | L12: 53259 | M12: 319.7
A13: =municipio!A13 -> 12 | B13: ='4 cha'!N35 -> 10 | C13: ='4 cha'!O35 -> 0 | D13: ='4 cha'!P35 -> 0 | F13: ='4 cha'!R35 -> 0 | H13: =SUM(B13:G15) -> 33 | I13: =municipio!B13 -> CHALATENANGO CENTRO | J13: ='4 cha'!J36 -> AGUA CALIENTE, DULCE NOMBRE DE MARIA, EL PARAISO, LA REINA, NUEVA CONCEPCION, SAN FERNANDO, SAN FRANCISCO MORAZAN, SAN RAFAEL, SANTA RITA, TEJUTLA | K13: 1018.45 | L13: 100658 | M13: 98.83
A14: =municipio!A14 -> 13 | E14: ='4 cha'!Q35 -> 3 | I14: =municipio!B14 -> CHALATENANGO NORTE | J14: ='4 cha'!J37 -> CITALA, LA PALMA, SAN IGNACIO | K14: 284.11 | L14: 54881 | M14: 193.17
A15: =municipio!A15 -> 14 | G15: ='4 cha'!S35 -> 20 | I15: =municipio!B15 -> CHALATENANGO SUR | J15: ='4 cha'!J38 -> ARCATAO, AZACUALPA, COMALAPA, CONCEPCION QUEZALTEPEQUE , CHALATENANGO, EL CARRIZAL, LA LAGUNA, LAS VUELTAS, NOMBRE DE JESUS, NUEVA TRINIDAD, OJOS DE AGUA, POTONICO, SAN ANTONIO DE LA CRUZ, SAN ANTONIO LOS RANCHOS, SAN FRANCISCO LEMPA, SAN ISIDRO LABRADOR, CANCASTE, SAN JOSE LAS FLORES, SAN LUIS DEL CARMEN, SAN MIGUEL DE MERCEDES | K15: 713.99 | L15: 74809 | M15: 104.78
A16: =municipio!A16 -> 15 | B16: ='5 LL'!N24 -> 2 | H16: =SUM(B16:G21) -> 22 | I16: =municipio!B16 -> LA LIBERTAD CENTRO | J16: ='5 LL'!K25 -> CIUDAD ARCE, SAN JUAN OPICO | K16: 305.7 | L16: 141280 | M16: 462.15
A17: =municipio!A17 -> 16 | C17: ='5 LL'!O24 -> 4 | I17: =municipio!B17 -> LA LIBERTAD COSTA | J17: ='5 LL'!K26 -> JICALAPA, LA LIBERTAD, TAMANIQUE, TEOTEPEQUE | K17: 440.98 | L17: 79906 | M17: 181.2
A18: =municipio!A18 -> 17 | D18: ='5 LL'!P24 -> 5 | I18: =municipio!B18 -> LA LIBERTAD ESTE | J18: ='5 LL'!K27 -> ANTIGUO CUSCATLAN, HUIZUCAR, NUEVO CUSCATLAN, SAN JOSE VILLANUEVA, ZARAGOZA | K18: 134.58 | L18: 132697 | M18: 986.01
A19: =municipio!A19 -> 18 | E19: ='5 LL'!Q24 -> 4 | I19: =municipio!B19 -> LA LIBERTAD NORTE | J19: ='5 LL'!K28 -> CHILTIUPAN, QUEZALTEPEQUE, SAN MATIAS, SAN PABLO TACACHICO | K19: 307.39 | L19: 94800 | M19: 308.4
A20: =municipio!A20 -> 19 | F20: ='5 LL'!R24 -> 5 | I20: =municipio!B20 -> LA LIBERTAD OESTE | J20: ='5 LL'!K29 -> COLON, JAYAQUE, SACACOYO, TALNIQUE, TEPECOYO | K20: 276.98 | L20: 148980 | M20: 537.87
A21: =municipio!A21 -> 20 | G21: ='5 LL'!S24 -> 2 | I21: =municipio!B21 -> LA LIBERTAD SUR | J21: ='5 LL'!K30 -> COMASAGUA, SANTA TECLA | K21: 187.25 | L21: 135908 | M21: 725.81
A22: =municipio!A22 -> 21 | B22: ='6 ss'!N21 -> 5 | C22: ='6 ss'!O21 -> 0 | H22: =SUM(B22:G26) -> 19 | I22: =municipio!B22 -> SAN SALVADOR CENTRO | J22: ='6 ss'!K22 -> AYUTUXTEPEQUE, CUSCATANCINGO, MEJICANOS, SAN SALVADOR, CIUDAD DELGADO | K22: 141.6 | L22: 702061 | M22: 4958.06
A23: =municipio!A23 -> 22 | D23: ='6 ss'!P21 -> 4 | I23: =municipio!B23 -> SAN SALVADOR ESTE | J23: ='6 ss'!K23 -> ILOPANGO, SAN MARTIN, SOYAPANGO, TONACATEPEQUE | K23: 187.74 | L23: 550739 | M23: 2933.52
A24: =municipio!A24 -> 23 | E24: ='6 ss'!Q21 -> 3 | I24: =municipio!B24 -> SAN SALVADOR NORTE | J24: ='6 ss'!K24 -> AGUILARES, EL PAISNAL, GUAZAPA | K24: 222.86 | L24: 58724 | M24: 263.5
A25: =municipio!A25 -> 24 | F25: ='6 ss'!R21 -> 2 | I25: =municipio!B25 -> SAN SALVADOR OESTE | J25: ='6 ss'!K25 -> APOPA, NEJAPA | K25: 135.2 | L25: 227986 | M25: 1686.29
A26: =municipio!A26 -> 25 | G26: ='6 ss'!S21 -> 5 | I26: =municipio!B26 -> SAN SALVADOR SUR | J26: ='6 ss'!K26 -> PANCHIMALCO, ROSARIO DE MORA, SAN MARCOS, SANTIAGO TEXACUANGOS, SANTO TOMAS | K26: 198.75 | L26: 160618 | M26: 808.14
A27: =municipio!A27 -> 26 | B27: ='7 cus'!N18 -> 0 | C27: ='7 cus'!O18 -> 0 | D27: ='7 cus'!P18 -> 0 | E27: ='7 cus'!Q18 -> 6 | F27: ='7 cus'!R18 -> 0 | H27: =SUM(B27:G28) -> 16 | I27: =municipio!B27 -> CUSCATLÁN NORTE | J27: ='7 cus'!K19 -> ORATORIO DE CONCEPCION, SAN BARTOLOME PERULAPIA, SAN JOSE GUAYABAL, SAN PEDRO PERULAPAN, SANTA CRUZ ANALQUITO, SUCHITOTO | K27: 499.17 | L27: 90452 | M27: 181.2
A28: =municipio!A28 -> 27 | G28: ='7 cus'!S18 -> 10 | I28: =municipio!B28 -> CUSCATLÁN SUR | J28: ='7 cus'!K20 -> CANDELARIA, COJUTEPEQUE, EL CARMEN, EL ROSARIO CUSCATLAN, MONTE SAN JUAN, SAN CRISTOBAL, SAN RAFAEL CEDROS, SAN RAMON, SANTA CRUZ MICHAPA, TENANCINGO | K28: 257.02 | L28: 145713 | M28: 566.93
A29: =municipio!A29 -> 28 | B29: ='8 lp'!N24 -> 12 | C29: ='8 lp'!O24 -> 0 | E29: ='8 lp'!Q24 -> 0 | G29: ='8 lp'!S24 -> 0 | H29: =SUM(B29:G31) -> 22 | I29: =municipio!B29 -> LA PAZ CENTRO | J29: ='8 lp'!K25 -> EL ROSARIO, JERUSALEN, MERCEDES LA CEIBA, PARAISO DE OSORIO, SAN ANTONIO MASAHUAT, SAN EMIGDIO, SAN JUAN TEPEZONTES, SAN MIGUEL TEPEZONTES, SAN PEDRO NONUALCO, SANTA MARIA OSTUMA, SANTIAGO NONUALCO, SAN LUIS LA HERRADURA | K29: 450.42 | L29: 115564 | M29: 256.57
A30: =municipio!A30 -> 29 | D30: ='8 lp'!P24 -> 3 | I30: =municipio!B30 -> LA PAZ ESTE | J30: ='8 lp'!K26 -> SAN JUAN NONUALCO, SAN RAFAEL OBRAJUELO, ZACATECOLUCA | K30: 391.96 | L30: 96565 | M30: 246.36
A31: =municipio!A31 -> 30 | F31: ='8 lp'!R24 -> 7 | I31: =municipio!B31 -> LA PAZ OESTE | J31: ='8 lp'!K27 -> CUYULTITAN, OLOCUILTA, SAN FRANCISCO CHINAMECA, SAN JUAN TALPA, SAN LUIS TALPA, SAN PEDRO MASAHUAT, TAPALHUACA | K31: 381.23 | L31: 101279 | M31: 265.66
A32: =municipio!A32 -> 31 | B32: ='9 cab'!N11 -> 0 | C32: ='9 cab'!O11 -> 0 | D32: ='9 cab'!P11 -> 5 | E32: ='9 cab'!Q11 -> 0 | G32: ='9 cab'!S11 -> 0 | H32: =SUM(B32:G33) -> 9 | I32: =municipio!B32 -> CABAÑAS ESTE | J32: ='9 cab'!K13 -> GUACOTECTI, SAN ISIDRO, SENSUNTEPEQUE, VICTORIA, DOLORES | K32: 701.67 | L32: 66727 | M32: 95.1
A33: =municipio!A33 -> 32 | F33: ='9 cab'!R11 -> 4 | I33: =municipio!B33 -> CABAÑAS OESTE | J33: ='9 cab'!K14 -> CINQUERA, ILOBASCO, JUTIAPA, TEJUTEPEQUE | K33: 401.84 | L33: 86875 | M33: 216.19
A34: =municipio!A34 -> 33 | B34: ='10 sv'!N15 -> 0 | C34: ='10 sv'!O15 -> 0 | D34: ='10 sv'!P15 -> 0 | E34: ='10 sv'!Q15 -> 7 | F34: ='10 sv'!R15 -> 0 | H34: =SUM(B34:G35) -> 13 | I34: =municipio!B34 -> SAN VICENTE NORTE | J34: ='10 sv'!K16 -> APASTEPEQUE, SANTA CLARA, SANTO DOMINGO, SAN ESTEBAN CATARINA, SAN ILDEFONSO, SAN LORENZO, SAN SEBASTIAN | K34: 556.48 | L34: 70209 | M34: 126.17
A35: =municipio!A35 -> 34 | G35: ='10 sv'!S15 -> 6 | I35: =municipio!B35 -> SAN VICENTE SUR | J35: ='10 sv'!K17 -> GUADALUPE, SAN CAYETANO ISTEPEQUE, SAN VICENTE, TECOLUCA, TEPETITAN, VERAPAZ | K35: 627.54 | L35: 99893 | M35: 159.18
A36: =municipio!A36 -> 35 | B36: ='11 usu'!N25 -> 0 | C36: ='11 usu'!O25 -> 0 | D36: ='11 usu'!P25 -> 10 | G36: ='11 usu'!S25 -> 0 | H36: =SUM(B36:G38) -> 23 | I36: =municipio!B36 -> USULUTÁN ESTE | J36: ='11 usu'!K26 -> CALIFORNIA, CONCEPCION BATRES, EREGUAYQUIN, JUCUARAN, OZATLAN, SAN DIONISIO, SANTA ELENA, SANTA MARIA, TECAPAN, USULUTAN | K36: 831.32 | L36: 160590 | M36: 193.17
A37: =municipio!A37 -> 36 | E37: ='11 usu'!Q25 -> 9 | I37: =municipio!B37 -> USULUTÁN NORTE | J37: ='11 usu'!K27 -> ALEGRIA, BERLIN, EL TRIUNFO, ESTANZUELAS, JUCUAPA, MERCEDES UMAÑA, NUEVA GRANADA, SAN BUENAVENTURA, SANTIAGO DE MARIA | K37: 551.69 | L37: 109367 | M37: 198.24
A38: =municipio!A38 -> 37 | F38: ='11 usu'!R25 -> 4 | I38: =municipio!B38 -> USULUTÁN OESTE | J38: ='11 usu'!K28 -> JIQUILISCO, PUERTO EL TRIUNFO, SAN AGUSTIN, SAN FRANCISCO JAVIER | K38: 747.43 | L38: 79311 | M38: 106.11
A39: =municipio!A39 -> 38 | B39: ='12 sm'!N22 -> 6 | C39: ='12 sm'!O22 -> 0 | D39: ='12 sm'!P22 -> 0 | G39: ='12 sm'!S22 -> 0 | H39: =SUM(B39:G41) -> 20 | I39: =municipio!B39 -> SAN MIGUEL CENTRO | J39: ='12 sm'!K23 -> COMACARAN, CHIRILAGUA, MONCAGUA, QUELEPA, SAN MIGUEL, ULUAZAPA | K39: 997.08 | L39: 398361 | M39: 399.53
A40: =municipio!A40 -> 39 | E40: ='12 sm'!Q22 -> 8 | I40: =municipio!B40 -> SAN MIGUEL NORTE | J40: ='12 sm'!K24 -> CAROLINA, CIUDAD BARRIOS, CHAPELTIQUE, NUEVO EDEN DE SAN JUAN, SAN ANTONIO DEL MOSCO, SAN GERARDO, SAN LUIS DE LA REINA, SESORI | K40: 758.96 | L40: 79611 | M40: 104.89
...

Sheet N TRIBUTARIO
A1: CODIZONAL | B1: DIA | C1: MES | D1: AÑO | E1: SERIE | F1: CODIGO | G1: NUMERO | H1: CORRELATIVO | I1: # DE DEPARTAMENTO | J1: NOMBRE DE DISTRITO | K1: ZONA | L1: NOMBRE DEPARTAMENTO | M1: CENTRO | N1: COSTA | O1: ESTE | P1: NORTE | Q1: OESTE | R1: SUR | S1: NO DETERMINADO | V1: DISTCODIGOZONA | W1: NITDIST | X1: NOMBRE DISTRITO ZONA | Y1: NIT DISTRITO NOMBRE ZONA | Z1: CODIGO NOMBRE ZONA | AA1: AREA (KM2) | AB1: POBLACION | AC1: DENSIDAD (HAB./KM2)
A2: 1C | B2: 01 | C2: 06 | D2: 11 | E2: 001 | F2: 0 | G2: =[1]DISTRITOS!A2 -> 1 | H2: 0101 | I2: =[2]DEPARTAMENTOS!A2 -> 1 | J2: AHUACHAPAN | K2: CENTRO | L2: AHUACHAPAN | M2: 1 | T2: - | V2: =CONCATENATE(J2,T2,H2,T2,K2) -> AHUACHAPAN-0101-CENTRO | W2: =CONCATENATE(H2,T2,B2,C2,D2,T2,E2,T2,F2) -> 0101-010611-001-0 | X2: =CONCATENATE(J2,U2,K2) -> AHUACHAPAN CENTRO | Y2: =CONCATENATE(W2,U2,X2) -> 0101-010611-001-0 AHUACHAPAN CENTRO | Z2: =CONCATENATE(H2,U2,J2,T2,K2) -> 0101 AHUACHAPAN-CENTRO | AA2: 501.01 | AB2: 237889 | AC2: 474.82
B3: 01 | C3: 10 | D3: 79 | E3: 001 | F3: 9 | G3: =[1]DISTRITOS!A3 -> 2 | H3: 0102 | J3: APANECA | K3: CENTRO | L3: AHUACHAPAN | M3: 1 | T3: - | V3: =CONCATENATE(J3,T3,H3,T3,K3) -> APANECA-0102-CENTRO | W3: =CONCATENATE(H3,T3,B3,C3,D3,T3,E3,T3,F3) -> 0102-011079-001-9 | X3: =CONCATENATE(J3,U3,K3) -> APANECA CENTRO | Y3: =CONCATENATE(W3,U3,X3) -> 0102-011079-001-9 APANECA CENTRO | Z3: =CONCATENATE(H3,U3,J3,T3,K3) -> 0102 APANECA-CENTRO
A4: N1 | B4: 01 | C4: 10 | D4: 79 | E4: 001 | F4: 9 | G4: =[1]DISTRITOS!A4 -> 3 | H4: 0103 | J4: ATIQUIZAYA | K4: NORTE | L4: AHUACHAPAN | P4: 1 | T4: - | V4: =CONCATENATE(J4,T4,H4,T4,K4) -> ATIQUIZAYA-0103-NORTE | W4: =CONCATENATE(H4,T4,B4,C4,D4,T4,E4,T4,F4) -> 0103-011079-001-9 | X4: =CONCATENATE(J4,U4,K4) -> ATIQUIZAYA NORTE | Y4: =CONCATENATE(W4,U4,X4) -> 0103-011079-001-9 ATIQUIZAYA NORTE | Z4: =CONCATENATE(H4,U4,J4,T4,K4) -> 0103 ATIQUIZAYA-NORTE | AA4: 146.89 | AB4: 61720 | AC4: 420.18
B5: 01 | C5: 10 | D5: 79 | E5: 001 | F5: 9 | G5: =[1]DISTRITOS!A5 -> 4 | H5: 0104 | J5: CONCEPCION DE ATACO | K5: CENTRO | L5: AHUACHAPAN | M5: 1 | T5: - | V5: =CONCATENATE(J5,T5,H5,T5,K5) -> CONCEPCION DE ATACO-0104-CENTRO | W5: =CONCATENATE(H5,T5,B5,C5,D5,T5,E5,T5,F5) -> 0104-011079-001-9 | X5: =CONCATENATE(J5,U5,K5) -> CONCEPCION DE ATACO CENTRO | Y5: =CONCATENATE(W5,U5,X5) -> 0104-011079-001-9 CONCEPCION DE ATACO CENTRO | Z5: =CONCATENATE(H5,U5,J5,T5,K5) -> 0104 CONCEPCION DE ATACO-CENTRO
B6: 01 | C6: 10 | D6: 79 | E6: 001 | F6: 9 | G6: =[1]DISTRITOS!A6 -> 5 | H6: 0105 | J6: EL REFUGIO | K6: NORTE | L6: AHUACHAPAN | P6: 1 | T6: - | V6: =CONCATENATE(J6,T6,H6,T6,K6) -> EL REFUGIO-0105-NORTE | W6: =CONCATENATE(H6,T6,B6,C6,D6,T6,E6,T6,F6) -> 0105-011079-001-9 | X6: =CONCATENATE(J6,U6,K6) -> EL REFUGIO NORTE | Y6: =CONCATENATE(W6,U6,X6) -> 0105-011079-001-9 EL REFUGIO NORTE | Z6: =CONCATENATE(H6,U6,J6,T6,K6) -> 0105 EL REFUGIO-NORTE
A7: S1 | B7: 01 | C7: 10 | D7: 79 | E7: 001 | F7: 9 | G7: =[1]DISTRITOS!A7 -> 6 | H7: 0106 | J7: GUAYMANGO | K7: SUR | L7: AHUACHAPAN | R7: 1 | T7: - | V7: =CONCATENATE(J7,T7,H7,T7,K7) -> GUAYMANGO-0106-SUR | W7: =CONCATENATE(H7,T7,B7,C7,D7,T7,E7,T7,F7) -> 0106-011079-001-9 | X7: =CONCATENATE(J7,U7,K7) -> GUAYMANGO SUR | Y7: =CONCATENATE(W7,U7,X7) -> 0106-011079-001-9 GUAYMANGO SUR | Z7: =CONCATENATE(H7,U7,J7,T7,K7) -> 0106 GUAYMANGO-SUR | AA7: 591.43 | AB7: 102457 | AC7: 173.24
B8: 01 | C8: 10 | D8: 79 | E8: 001 | F8: 9 | G8: =[1]DISTRITOS!A8 -> 7 | H8: 0107 | J8: JUJUTLA | K8: SUR | L8: AHUACHAPAN | R8: 1 | T8: - | V8: =CONCATENATE(J8,T8,H8,T8,K8) -> JUJUTLA-0107-SUR | W8: =CONCATENATE(H8,T8,B8,C8,D8,T8,E8,T8,F8) -> 0107-011079-001-9 | X8: =CONCATENATE(J8,U8,K8) -> JUJUTLA SUR | Y8: =CONCATENATE(W8,U8,X8) -> 0107-011079-001-9 JUJUTLA SUR | Z8: =CONCATENATE(H8,U8,J8,T8,K8) -> 0107 JUJUTLA-SUR
B9: 01 | C9: 10 | D9: 79 | E9: 001 | F9: 2 | G9: =[1]DISTRITOS!A9 -> 8 | H9: 0108 | J9: SAN FRANCISCO MENENDEZ | K9: SUR | L9: AHUACHAPAN | R9: 1 | T9: - | V9: =CONCATENATE(J9,T9,H9,T9,K9) -> SAN FRANCISCO MENENDEZ-0108-SUR | W9: =CONCATENATE(H9,T9,B9,C9,D9,T9,E9,T9,F9) -> 0108-011079-001-2 | X9: =CONCATENATE(J9,U9,K9) -> SAN FRANCISCO MENENDEZ SUR | Y9: =CONCATENATE(W9,U9,X9) -> 0108-011079-001-2 SAN FRANCISCO MENENDEZ SUR | Z9: =CONCATENATE(H9,U9,J9,T9,K9) -> 0108 SAN FRANCISCO MENENDEZ-SUR
B10: 01 | C10: 10 | D10: 79 | E10: 001 | F10: 9 | G10: =[1]DISTRITOS!A10 -> 9 | H10: 0109 | J10: SAN LORENZO | K10: NORTE | L10: AHUACHAPAN | P10: 1 | T10: - | V10: =CONCATENATE(J10,T10,H10,T10,K10) -> SAN LORENZO-0109-NORTE | W10: =CONCATENATE(H10,T10,B10,C10,D10,T10,E10,T10,F10) -> 0109-011079-001-9 | X10: =CONCATENATE(J10,U10,K10) -> SAN LORENZO NORTE | Y10: =CONCATENATE(W10,U10,X10) -> 0109-011079-001-9 SAN LORENZO NORTE | Z10: =CONCATENATE(H10,U10,J10,T10,K10) -> 0109 SAN LORENZO-NORTE
B11: 01 | C11: 10 | D11: 79 | E11: 001 | F11: 0 | G11: =[1]DISTRITOS!A11 -> 10 | H11: 0110 | J11: SAN PEDRO PUXTLA | K11: SUR | L11: AHUACHAPAN | R11: 1 | T11: - | V11: =CONCATENATE(J11,T11,H11,T11,K11) -> SAN PEDRO PUXTLA-0110-SUR | W11: =CONCATENATE(H11,T11,B11,C11,D11,T11,E11,T11,F11) -> 0110-011079-001-0 | X11: =CONCATENATE(J11,U11,K11) -> SAN PEDRO PUXTLA SUR | Y11: =CONCATENATE(W11,U11,X11) -> 0110-011079-001-0 SAN PEDRO PUXTLA SUR | Z11: =CONCATENATE(H11,U11,J11,T11,K11) -> 0110 SAN PEDRO PUXTLA-SUR
B12: 01 | C12: 10 | D12: 79 | E12: 001 | F12: 0 | G12: =[1]DISTRITOS!A12 -> 11 | H12: 0111 | J12: TACUBA | K12: CENTRO | L12: AHUACHAPAN | M12: 1 | T12: - | V12: =CONCATENATE(J12,T12,H12,T12,K12) -> TACUBA-0111-CENTRO | W12: =CONCATENATE(H12,T12,B12,C12,D12,T12,E12,T12,F12) -> 0111-011079-001-0 | X12: =CONCATENATE(J12,U12,K12) -> TACUBA CENTRO | Y12: =CONCATENATE(W12,U12,X12) -> 0111-011079-001-0 TACUBA CENTRO | Z12: =CONCATENATE(H12,U12,J12,T12,K12) -> 0111 TACUBA-CENTRO
B13: 01 | C13: 10 | D13: 79 | E13: 001 | F13: 0 | G13: =[1]DISTRITOS!A13 -> 12 | H13: 0112 | J13: TURIN | K13: NORTE | L13: AHUACHAPAN | P13: 1 | T13: - | V13: =CONCATENATE(J13,T13,H13,T13,K13) -> TURIN-0112-NORTE | W13: =CONCATENATE(H13,T13,B13,C13,D13,T13,E13,T13,F13) -> 0112-011079-001-0 | X13: =CONCATENATE(J13,U13,K13) -> TURIN NORTE | Y13: =CONCATENATE(W13,U13,X13) -> 0112-011079-001-0 TURIN NORTE | Z13: =CONCATENATE(H13,U13,J13,T13,K13) -> 0112 TURIN-NORTE
A14: O1 | B14: 01 | C14: 10 | D14: 79 | E14: 001 | F14: 9 | G14: =[1]DISTRITOS!A14 -> 13 | H14: 0201 | J14: CANDELARIA DE LA FRONTERA | K14: OESTE | L14: SANTA ANA | Q14: 1 | T14: - | V14: =CONCATENATE(J14,T14,H14,T14,K14) -> CANDELARIA DE LA FRONTERA-0201-OESTE | W14: =CONCATENATE(H14,T14,B14,C14,D14,T14,E14,T14,F14) -> 0201-011079-001-9 | X14: =CONCATENATE(J14,U14,K14) -> CANDELARIA DE LA FRONTERA OESTE | Y14: =CONCATENATE(W14,U14,X14) -> 0201-011079-001-9 CANDELARIA DE LA FRONTERA OESTE | Z14: =CONCATENATE(H14,U14,J14,T14,K14) -> 0201 CANDELARIA DE LA FRONTERA-OESTE | AA14: 447.87 | AB14: 172035 | AC14: 384.12
A15: E1 | B15: 01 | C15: 06 | D15: 11 | E15: 001 | F15: 2 | G15: =[1]DISTRITOS!A15 -> 14 | H15: 0202 | J15: COATEPEQUE | K15: ESTE | L15: SANTA ANA | O15: 1 | T15: - | V15: =CONCATENATE(J15,T15,H15,T15,K15) -> COATEPEQUE-0202-ESTE | W15: =CONCATENATE(H15,T15,B15,C15,D15,T15,E15,T15,F15) -> 0202-010611-001-2 | X15: =CONCATENATE(J15,U15,K15) -> COATEPEQUE ESTE | Y15: =CONCATENATE(W15,U15,X15) -> 0202-010611-001-2 COATEPEQUE ESTE | Z15: =CONCATENATE(H15,U15,J15,T15,K15) -> 0202 COATEPEQUE-ESTE | AA15: 218.28 | AB15: 64061 | AC15: 293.48
B16: 01 | C16: 06 | D16: 11 | E16: 001 | F16: 2 | G16: =[1]DISTRITOS!A16 -> 15 | H16: 0203 | J16: CHALCHUAPA | K16: OESTE | L16: SANTA ANA | Q16: 1 | T16: - | V16: =CONCATENATE(J16,T16,H16,T16,K16) -> CHALCHUAPA-0203-OESTE | W16: =CONCATENATE(H16,T16,B16,C16,D16,T16,E16,T16,F16) -> 0203-010611-001-2 | X16: =CONCATENATE(J16,U16,K16) -> CHALCHUAPA OESTE | Y16: =CONCATENATE(W16,U16,X16) -> 0203-010611-001-2 CHALCHUAPA OESTE | Z16: =CONCATENATE(H16,U16,J16,T16,K16) -> 0203 CHALCHUAPA-OESTE
B17: 02 | C17: 10 | D17: 79 | E17: 001 | F17: 9 | G17: =[1]DISTRITOS!A17 -> 16 | H17: 0204 | J17: EL CONGO | K17: ESTE | L17: SANTA ANA | O17: 1 | T17: - | V17: =CONCATENATE(J17,T17,H17,T17,K17) -> EL CONGO-0204-ESTE | W17: =CONCATENATE(H17,T17,B17,C17,D17,T17,E17,T17,F17) -> 0204-021079-001-9 | X17: =CONCATENATE(J17,U17,K17) -> EL CONGO ESTE | Y17: =CONCATENATE(W17,U17,X17) -> 0204-021079-001-9 EL CONGO ESTE | Z17: =CONCATENATE(H17,U17,J17,T17,K17) -> 0204 EL CONGO-ESTE
B18: 02 | C18: 10 | D18: 79 | E18: 001 | F18: 9 | G18: =[1]DISTRITOS!A18 -> 17 | H18: 0205 | J18: EL PORVENIR | K18: OESTE | L18: SANTA ANA | Q18: 1 | T18: - | V18: =CONCATENATE(J18,T18,H18,T18,K18) -> EL PORVENIR-0205-OESTE | W18: =CONCATENATE(H18,T18,B18,C18,D18,T18,E18,T18,F18) -> 0205-021079-001-9 | X18: =CONCATENATE(J18,U18,K18) -> EL PORVENIR OESTE | Y18: =CONCATENATE(W18,U18,X18) -> 0205-021079-001-9 EL PORVENIR OESTE | Z18: =CONCATENATE(H18,U18,J18,T18,K18) -> 0205 EL PORVENIR-OESTE
A19: N1 | B19: 02 | C19: 10 | D19: 79 | E19: 001 | F19: 9 | G19: =[1]DISTRITOS!A19 -> 18 | H19: 0206 | J19: MASAHUAT | K19: NORTE | L19: SANTA ANA | P19: 1 | T19: - | V19: =CONCATENATE(J19,T19,H19,T19,K19) -> MASAHUAT-0206-NORTE | W19: =CONCATENATE(H19,T19,B19,C19,D19,T19,E19,T19,F19) -> 0206-021079-001-9 | X19: =CONCATENATE(J19,U19,K19) -> MASAHUAT NORTE | Y19: =CONCATENATE(W19,U19,X19) -> 0206-021079-001-9 MASAHUAT NORTE | Z19: =CONCATENATE(H19,U19,J19,T19,K19) -> 0206 MASAHUAT-NORTE | AA19: 956.97 | AB19: 91108 | AC19: 95.2
B20: 01 | C20: 06 | D20: 11 | E20: 002 | F20: 4 | G20: =[1]DISTRITOS!A20 -> 19 | H20: 0207 | J20: METAPAN | K20: NORTE | L20: SANTA ANA | P20: 1 | T20: - | V20: =CONCATENATE(J20,T20,H20,T20,K20) -> METAPAN-0207-NORTE | W20: =CONCATENATE(H20,T20,B20,C20,D20,T20,E20,T20,F20) -> 0207-010611-002-4 | X20: =CONCATENATE(J20,U20,K20) -> METAPAN NORTE | Y20: =CONCATENATE(W20,U20,X20) -> 0207-010611-002-4 METAPAN NORTE | Z20: =CONCATENATE(H20,U20,J20,T20,K20) -> 0207 METAPAN-NORTE
B21: 02 | C21: 10 | D21: 79 | E21: 001 | F21: 9 | G21: =[1]DISTRITOS!A21 -> 20 | H21: 0208 | J21: SAN ANTONIO PAJONAL | K21: OESTE | L21: SANTA ANA | Q21: 1 | T21: - | V21: =CONCATENATE(J21,T21,H21,T21,K21) -> SAN ANTONIO PAJONAL-0208-OESTE | W21: =CONCATENATE(H21,T21,B21,C21,D21,T21,E21,T21,F21) -> 0208-021079-001-9 | X21: =CONCATENATE(J21,U21,K21) -> SAN ANTONIO PAJONAL OESTE | Y21: =CONCATENATE(W21,U21,X21) -> 0208-021079-001-9 SAN ANTONIO PAJONAL OESTE | Z21: =CONCATENATE(H21,U21,J21,T21,K21) -> 0208 SAN ANTONIO PAJONAL-OESTE
B22: 02 | C22: 10 | D22: 79 | E22: 001 | F22: 9 | G22: =[1]DISTRITOS!A22 -> 21 | H22: 0209 | J22: SAN SEBASTIAN SALITRILLO | K22: OESTE | L22: SANTA ANA | Q22: 1 | T22: - | V22: =CONCATENATE(J22,T22,H22,T22,K22) -> SAN SEBASTIAN SALITRILLO-0209-OESTE | W22: =CONCATENATE(H22,T22,B22,C22,D22,T22,E22,T22,F22) -> 0209-021079-001-9 | X22: =CONCATENATE(J22,U22,K22) -> SAN SEBASTIAN SALITRILLO OESTE | Y22: =CONCATENATE(W22,U22,X22) -> 0209-021079-001-9 SAN SEBASTIAN SALITRILLO OESTE | Z22: =CONCATENATE(H22,U22,J22,T22,K22) -> 0209 SAN SEBASTIAN SALITRILLO-OESTE
A23: 1C | B23: 02 | C23: 10 | D23: 79 | E23: 001 | F23: 5 | G23: =[1]DISTRITOS!A23 -> 22 | H23: 0210 | I23: =[2]DEPARTAMENTOS!A3 -> 2 | J23: SANTA ANA | K23: CENTRO | L23: SANTA ANA | M23: 1 | T23: - | V23: =CONCATENATE(J23,T23,H23,T23,K23) -> SANTA ANA-0210-CENTRO | W23: =CONCATENATE(H23,T23,B23,C23,D23,T23,E23,T23,F23) -> 0210-021079-001-5 | X23: =CONCATENATE(J23,U23,K23) -> SANTA ANA CENTRO | Y23: =CONCATENATE(W23,U23,X23) -> 0210-021079-001-5 SANTA ANA CENTRO | Z23: =CONCATENATE(H23,U23,J23,T23,K23) -> 0210 SANTA ANA-CENTRO | AA23: 400.05 | AB23: 264091 | AC23: 660.14
B24: 02 | C24: 10 | D24: 79 | E24: 001 | F24: 0 | G24: =[1]DISTRITOS!A24 -> 23 | H24: 0211 | J24: SANTA ROSA GUACHIPILIN | K24: NORTE | L24: SANTA ANA | P24: 1 | T24: - | V24: =CONCATENATE(J24,T24,H24,T24,K24) -> SANTA ROSA GUACHIPILIN-0211-NORTE | W24: =CONCATENATE(H24,T24,B24,C24,D24,T24,E24,T24,F24) -> 0211-021079-001-0 | X24: =CONCATENATE(J24,U24,K24) -> SANTA ROSA GUACHIPILIN NORTE | Y24: =CONCATENATE(W24,U24,X24) -> 0211-021079-001-0 SANTA ROSA GUACHIPILIN NORTE | Z24: =CONCATENATE(H24,U24,J24,T24,K24) -> 0211 SANTA ROSA GUACHIPILIN-NORTE
B25: 02 | C25: 10 | D25: 79 | E25: 001 | F25: 0 | G25: =[1]DISTRITOS!A25 -> 24 | H25: 0212 | J25: SANTIAGO DE LA FRONTERA | K25: OESTE | L25: SANTA ANA | Q25: 1 | T25: - | V25: =CONCATENATE(J25,T25,H25,T25,K25) -> SANTIAGO DE LA FRONTERA-0212-OESTE | W25: =CONCATENATE(H25,T25,B25,C25,D25,T25,E25,T25,F25) -> 0212-021079-001-0 | X25: =CONCATENATE(J25,U25,K25) -> SANTIAGO DE LA FRONTERA OESTE | Y25: =CONCATENATE(W25,U25,X25) -> 0212-021079-001-0 SANTIAGO DE LA FRONTERA OESTE | Z25: =CONCATENATE(H25,U25,J25,T25,K25) -> 0212 SANTIAGO DE LA FRONTERA-OESTE
B26: 02 | C26: 10 | D26: 79 | E26: 001 | F26: 0 | G26: =[1]DISTRITOS!A26 -> 25 | H26: 0213 | J26: TEXISTEPEQUE | K26: NORTE | L26: SANTA ANA | P26: 1 | T26: - | V26: =CONCATENATE(J26,T26,H26,T26,K26) -> TEXISTEPEQUE-0213-NORTE | W26: =CONCATENATE(H26,T26,B26,C26,D26,T26,E26,T26,F26) -> 0213-021079-001-0 | X26: =CONCATENATE(J26,U26,K26) -> TEXISTEPEQUE NORTE | Y26: =CONCATENATE(W26,U26,X26) -> 0213-021079-001-0 TEXISTEPEQUE NORTE | Z26: =CONCATENATE(H26,U26,J26,T26,K26) -> 0213 TEXISTEPEQUE-NORTE
A27: O1 | B27: 01 | C27: 06 | D27: 11 | E27: 001 | F27: 4 | G27: =[1]DISTRITOS!A27 -> 26 | H27: 0301 | J27: ACAJUTLA | K27: OESTE | L27: SONSONATE | Q27: 1 | T27: - | V27: =CONCATENATE(J27,T27,H27,T27,K27) -> ACAJUTLA-0301-OESTE | W27: =CONCATENATE(H27,T27,B27,C27,D27,T27,E27,T27,F27) -> 0301-010611-001-4 | X27: =CONCATENATE(J27,U27,K27) -> ACAJUTLA OESTE | Y27: =CONCATENATE(W27,U27,X27) -> 0301-010611-001-4 ACAJUTLA OESTE | Z27: =CONCATENATE(H27,U27,J27,T27,K27) -> 0301 ACAJUTLA-OESTE | AA27: 166.59 | AB27: 53259 | AC27: 319.7
A28: E1 | B28: 23 | C28: 02 | D28: 78 | E28: 001 | F28: 8 | G28: =[1]DISTRITOS!A28 -> 27 | H28: 0302 | J28: ARMENIA | K28: ESTE | L28: SONSONATE | O28: 1 | T28: - | V28: =CONCATENATE(J28,T28,H28,T28,K28) -> ARMENIA-0302-ESTE | W28: =CONCATENATE(H28,T28,B28,C28,D28,T28,E28,T28,F28) -> 0302-230278-001-8 | X28: =CONCATENATE(J28,U28,K28) -> ARMENIA ESTE | Y28: =CONCATENATE(W28,U28,X28) -> 0302-230278-001-8 ARMENIA ESTE | Z28: =CONCATENATE(H28,U28,J28,T28,K28) -> 0302 ARMENIA-ESTE | AA28: 542.89 | AB28: 160035 | AC28: 294.78
B29: 03 | C29: 10 | D29: 79 | E29: 001 | F29: 9 | G29: =[1]DISTRITOS!A29 -> 28 | H29: 0303 | J29: CALUCO | K29: ESTE | L29: SONSONATE | O29: 1 | T29: - | V29: =CONCATENATE(J29,T29,H29,T29,K29) -> CALUCO-0303-ESTE | W29: =CONCATENATE(H29,T29,B29,C29,D29,T29,E29,T29,F29) -> 0303-031079-001-9 | X29: =CONCATENATE(J29,U29,K29) -> CALUCO ESTE | Y29: =CONCATENATE(W29,U29,X29) -> 0303-031079-001-9 CALUCO ESTE | Z29: =CONCATENATE(H29,U29,J29,T29,K29) -> 0303 CALUCO-ESTE
B30: 03 | C30: 10 | D30: 79 | E30: 001 | F30: 9 | G30: =[1]DISTRITOS!A30 -> 29 | H30: 0304 | J30: CUISNAHUAT | K30: ESTE | L30: SONSONATE | O30: 1 | T30: - | V30: =CONCATENATE(J30,T30,H30,T30,K30) -> CUISNAHUAT-0304-ESTE | W30: =CONCATENATE(H30,T30,B30,C30,D30,T30,E30,T30,F30) -> 0304-031079-001-9 | X30: =CONCATENATE(J30,U30,K30) -> CUISNAHUAT ESTE | Y30: =CONCATENATE(W30,U30,X30) -> 0304-031079-001-9 CUISNAHUAT ESTE | Z30: =CONCATENATE(H30,U30,J30,T30,K30) -> 0304 CUISNAHUAT-ESTE
B31: 03 | C31: 10 | D31: 79 | E31: 001 | F31: 9 | G31: =[1]DISTRITOS!A31 -> 30 | H31: 0305 | J31: SANTA ISABEL ISHUATAN | K31: ESTE | L31: SONSONATE | O31: 1 | T31: - | V31: =CONCATENATE(J31,T31,H31,T31,K31) -> SANTA ISABEL ISHUATAN-0305-ESTE | W31: =CONCATENATE(H31,T31,B31,C31,D31,T31,E31,T31,F31) -> 0305-031079-001-9 | X31: =CONCATENATE(J31,U31,K31) -> SANTA ISABEL ISHUATAN ESTE | Y31: =CONCATENATE(W31,U31,X31) -> 0305-031079-001-9 SANTA ISABEL ISHUATAN ESTE | Z31: =CONCATENATE(H31,U31,J31,T31,K31) -> 0305 SANTA ISABEL ISHUATAN-ESTE
B32: 01 | C32: 06 | D32: 11 | E32: 001 | F32: 4 | G32: =[1]DISTRITOS!A32 -> 31 | H32: 0306 | J32: IZALCO | K32: ESTE | L32: SONSONATE | O32: 1 | T32: - | V32: =CONCATENATE(J32,T32,H32,T32,K32) -> IZALCO-0306-ESTE | W32: =CONCATENATE(H32,T32,B32,C32,D32,T32,E32,T32,F32) -> 0306-010611-001-4 | X32: =CONCATENATE(J32,U32,K32) -> IZALCO ESTE | Y32: =CONCATENATE(W32,U32,X32) -> 0306-010611-001-4 IZALCO ESTE | Z32: =CONCATENATE(H32,U32,J32,T32,K32) -> 0306 IZALCO-ESTE
A33: N1 | B33: 01 | C33: 06 | D33: 11 | E33: 001 | F33: 4 | G33: =[1]DISTRITOS!A33 -> 32 | H33: 0307 | J33: JUAYUA | K33: NORTE | L33: SONSONATE | P33: 1 | T33: - | V33: =CONCATENATE(J33,T33,H33,T33,K33) -> JUAYUA-0307-NORTE | W33: =CONCATENATE(H33,T33,B33,C33,D33,T33,E33,T33,F33) -> 0307-010611-001-4 | X33: =CONCATENATE(J33,U33,K33) -> JUAYUA NORTE | Y33: =CONCATENATE(W33,U33,X33) -> 0307-010611-001-4 JUAYUA NORTE | Z33: =CONCATENATE(H33,U33,J33,T33,K33) -> 0307 JUAYUA-NORTE | AA33: 186.91 | AB33: 89106 | AC33: 476.73
B34: 01 | C34: 06 | D34: 11 | E34: 001 | F34: 4 | G34: =[1]DISTRITOS!A34 -> 33 | H34: 0308 | J34: NAHUIZALCO | K34: NORTE | L34: SONSONATE | P34: 1 | T34: - | V34: =CONCATENATE(J34,T34,H34,T34,K34) -> NAHUIZALCO-0308-NORTE | W34: =CONCATENATE(H34,T34,B34,C34,D34,T34,E34,T34,F34) -> 0308-010611-001-4 | X34: =CONCATENATE(J34,U34,K34) -> NAHUIZALCO NORTE | Y34: =CONCATENATE(W34,U34,X34) -> 0308-010611-001-4 NAHUIZALCO NORTE | Z34: =CONCATENATE(H34,U34,J34,T34,K34) -> 0308 NAHUIZALCO-NORTE
B35: 03 | C35: 10 | D35: 79 | E35: 001 | F35: 9 | G35: =[1]DISTRITOS!A35 -> 34 | H35: 0309 | J35: NAHULINGO | K35: CENTRO | L35: SONSONATE | M35: 1 | T35: - | V35: =CONCATENATE(J35,T35,H35,T35,K35) -> NAHULINGO-0309-CENTRO | W35: =CONCATENATE(H35,T35,B35,C35,D35,T35,E35,T35,F35) -> 0309-031079-001-9 | X35: =CONCATENATE(J35,U35,K35) -> NAHULINGO CENTRO | Y35: =CONCATENATE(W35,U35,X35) -> 0309-031079-001-9 NAHULINGO CENTRO | Z35: =CONCATENATE(H35,U35,J35,T35,K35) -> 0309 NAHULINGO-CENTRO
B36: 03 | C36: 10 | D36: 79 | E36: 001 | F36: 0 | G36: =[1]DISTRITOS!A36 -> 35 | H36: 0310 | J36: SALCOATITAN | K36: NORTE | L36: SONSONATE | P36: 1 | T36: - | V36: =CONCATENATE(J36,T36,H36,T36,K36) -> SALCOATITAN-0310-NORTE | W36: =CONCATENATE(H36,T36,B36,C36,D36,T36,E36,T36,F36) -> 0310-031079-001-0 | X36: =CONCATENATE(J36,U36,K36) -> SALCOATITAN NORTE | Y36: =CONCATENATE(W36,U36,X36) -> 0310-031079-001-0 SALCOATITAN NORTE | Z36: =CONCATENATE(H36,U36,J36,T36,K36) -> 0310 SALCOATITAN-NORTE
B37: 03 | C37: 10 | D37: 79 | E37: 001 | F37: 0 | G37: =[1]DISTRITOS!A37 -> 36 | H37: 0311 | J37: SAN ANTONIO DEL MONTE | K37: CENTRO | L37: SONSONATE | M37: 1 | T37: - | V37: =CONCATENATE(J37,T37,H37,T37,K37) -> SAN ANTONIO DEL MONTE-0311-CENTRO | W37: =CONCATENATE(H37,T37,B37,C37,D37,T37,E37,T37,F37) -> 0311-031079-001-0 | X37: =CONCATENATE(J37,U37,K37) -> SAN ANTONIO DEL MONTE CENTRO | Y37: =CONCATENATE(W37,U37,X37) -> 0311-031079-001-0 SAN ANTONIO DEL MONTE CENTRO | Z37: =CONCATENATE(H37,U37,J37,T37,K37) -> 0311 SAN ANTONIO DEL MONTE-CENTRO
B38: 03 | C38: 10 | D38: 79 | E38: 001 | F38: 0 | G38: =[1]DISTRITOS!A38 -> 37 | H38: 0312 | J38: SAN JULIAN | K38: ESTE | L38: SONSONATE | O38: 1 | T38: - | V38: =CONCATENATE(J38,T38,H38,T38,K38) -> SAN JULIAN-0312-ESTE | W38: =CONCATENATE(H38,T38,B38,C38,D38,T38,E38,T38,F38) -> 0312-031079-001-0 | X38: =CONCATENATE(J38,U38,K38) -> SAN JULIAN ESTE | Y38: =CONCATENATE(W38,U38,X38) -> 0312-031079-001-0 SAN JULIAN ESTE | Z38: =CONCATENATE(H38,U38,J38,T38,K38) -> 0312 SAN JULIAN-ESTE
B39: 03 | C39: 10 | D39: 79 | E39: 001 | F39: 0 | G39: =[1]DISTRITOS!A39 -> 38 | H39: 0313 | J39: SANTA CATARINA MASAHUAT | K39: NORTE | L39: SONSONATE | P39: 1 | T39: - | V39: =CONCATENATE(J39,T39,H39,T39,K39) -> SANTA CATARINA MASAHUAT-0313-NORTE | W39: =CONCATENATE(H39,T39,B39,C39,D39,T39,E39,T39,F39) -> 0313-031079-001-0 | X39: =CONCATENATE(J39,U39,K39) -> SANTA CATARINA MASAHUAT NORTE | Y39: =CONCATENATE(W39,U39,X39) -> 0313-031079-001-0 SANTA CATARINA MASAHUAT NORTE | Z39: =CONCATENATE(H39,U39,J39,T39,K39) -> 0313 SANTA CATARINA MASAHUAT-NORTE
B40: 03 | C40: 10 | D40: 79 | E40: 001 | F40: 0 | G40: =[1]DISTRITOS!A40 -> 39 | H40: 0314 | J40: SANTO DOMINGO DE GUZMAN | K40: CENTRO | L40: SONSONATE | M40: 1 | T40: - | V40: =CONCATENATE(J40,T40,H40,T40,K40) -> SANTO DOMINGO DE GUZMAN-0314-CENTRO | W40: =CONCATENATE(H40,T40,B40,C40,D40,T40,E40,T40,F40) -> 0314-031079-001-0 | X40: =CONCATENATE(J40,U40,K40) -> SANTO DOMINGO DE GUZMAN CENTRO | Y40: =CONCATENATE(W40,U40,X40) -> 0314-031079-001-0 SANTO DOMINGO DE GUZMAN CENTRO | Z40: =CONCATENATE(H40,U40,J40,T40,K40) -> 0314 SANTO DOMINGO DE GUZMAN-CENTRO
...

Sheet 14 LU
A1: CODIZONAL | B1: DIA | C1: MES | D1: AÑO | E1: SERIE | F1: CODIGO | G1: NUMERO | H1: CORRELATIVO | I1: # DE DEPARTAMENTO | K1: NOMBRE DE DISTRITO | L1: ZONA | M1: NOMBRE DEPARTAMENTO | N1: CENTRO | O1: COSTA | P1: ESTE | Q1: NORTE | R1: OESTE | S1: SUR | T1: NO DETERMINADO | W1: DISTCODIGOZONA | X1: NITDIST | Y1: NOMBRE DISTRITO ZONA | Z1: NIT DISTRITO NOMBRE ZONA | AA1: CODIGO NOMBRE ZONA | AB1: AREA (KM2) | AC1: POBLACION | AD1: DENSIDAD (HAB./KM2)
A2: ='N TRIBUTARIO'!A246 -> N1 | B2: ='N TRIBUTARIO'!B246 -> 14 | C2: ='N TRIBUTARIO'!C246 -> 10 | D2: ='N TRIBUTARIO'!D246 -> 79 | E2: ='N TRIBUTARIO'!E246 -> 001 | F2: ='N TRIBUTARIO'!F246 -> 0 | G2: ='N TRIBUTARIO'!G246 -> 245 | H2: ='N TRIBUTARIO'!H246 -> 1401 | I2: ='N TRIBUTARIO'!I246 -> 0 | J2: , | K2: ='N TRIBUTARIO'!J246 -> ANAMOROS | L2: ='N TRIBUTARIO'!K246 -> NORTE | M2: ='N TRIBUTARIO'!L246 -> LA UNION | N2: ='N TRIBUTARIO'!M246 -> 0 | O2: ='N TRIBUTARIO'!N246 -> 0 | P2: ='N TRIBUTARIO'!O246 -> 0 | Q2: ='N TRIBUTARIO'!P246 -> 1 | R2: ='N TRIBUTARIO'!Q246 -> 0 | ... AD2: ='N TRIBUTARIO'!AC246 -> 99.77
A3: ='N TRIBUTARIO'!A247 -> 0 | B3: ='N TRIBUTARIO'!B247 -> 14 | C3: ='N TRIBUTARIO'!C247 -> 10 | D3: ='N TRIBUTARIO'!D247 -> 79 | E3: ='N TRIBUTARIO'!E247 -> 001 | F3: ='N TRIBUTARIO'!F247 -> 0 | G3: ='N TRIBUTARIO'!G247 -> 246 | H3: ='N TRIBUTARIO'!H247 -> 1402 | I3: ='N TRIBUTARIO'!I247 -> 0 | J3: , | K3: ='N TRIBUTARIO'!J247 -> BOLIVAR | L3: ='N TRIBUTARIO'!K247 -> NORTE | M3: ='N TRIBUTARIO'!L247 -> LA UNION | N3: ='N TRIBUTARIO'!M247 -> 0 | O3: ='N TRIBUTARIO'!N247 -> 0 | P3: ='N TRIBUTARIO'!O247 -> 0 | Q3: ='N TRIBUTARIO'!P247 -> 1 | R3: ='N TRIBUTARIO'!Q247 -> 0 | ... AD3: ='N TRIBUTARIO'!AC247 -> 0
A4: ='N TRIBUTARIO'!A248 -> 0 | B4: ='N TRIBUTARIO'!B248 -> 14 | C4: ='N TRIBUTARIO'!C248 -> 10 | D4: ='N TRIBUTARIO'!D248 -> 79 | E4: ='N TRIBUTARIO'!E248 -> 001 | F4: ='N TRIBUTARIO'!F248 -> 0 | G4: ='N TRIBUTARIO'!G248 -> 247 | H4: ='N TRIBUTARIO'!H248 -> 1403 | I4: ='N TRIBUTARIO'!I248 -> 0 | J4: , | K4: ='N TRIBUTARIO'!J248 -> CONCEPCION DE ORIENTE | L4: ='N TRIBUTARIO'!K248 -> NORTE | M4: ='N TRIBUTARIO'!L248 -> LA UNION | N4: ='N TRIBUTARIO'!M248 -> 0 | O4: ='N TRIBUTARIO'!N248 -> 0 | P4: ='N TRIBUTARIO'!O248 -> 0 | Q4: ='N TRIBUTARIO'!P248 -> 1 | R4: ='N TRIBUTARIO'!Q248 -> 0 | ... AD4: ='N TRIBUTARIO'!AC248 -> 0
A5: ='N TRIBUTARIO'!A249 -> S1 | B5: ='N TRIBUTARIO'!B249 -> 14 | C5: ='N TRIBUTARIO'!C249 -> 10 | D5: ='N TRIBUTARIO'!D249 -> 79 | E5: ='N TRIBUTARIO'!E249 -> 001 | F5: ='N TRIBUTARIO'!F249 -> 0 | G5: ='N TRIBUTARIO'!G249 -> 248 | H5: ='N TRIBUTARIO'!H249 -> 1404 | I5: ='N TRIBUTARIO'!I249 -> 0 | J5: , | K5: ='N TRIBUTARIO'!J249 -> CONCHAGUA | L5: ='N TRIBUTARIO'!K249 -> SUR | M5: ='N TRIBUTARIO'!L249 -> LA UNION | N5: ='N TRIBUTARIO'!M249 -> 0 | O5: ='N TRIBUTARIO'!N249 -> 0 | P5: ='N TRIBUTARIO'!O249 -> 0 | Q5: ='N TRIBUTARIO'!P249 -> 0 | R5: ='N TRIBUTARIO'!Q249 -> 0 | ... AD5: ='N TRIBUTARIO'!AC249 -> 136.02
A6: ='N TRIBUTARIO'!A250 -> 0 | B6: ='N TRIBUTARIO'!B250 -> 14 | C6: ='N TRIBUTARIO'!C250 -> 10 | D6: ='N TRIBUTARIO'!D250 -> 79 | E6: ='N TRIBUTARIO'!E250 -> 001 | F6: ='N TRIBUTARIO'!F250 -> 0 | G6: ='N TRIBUTARIO'!G250 -> 249 | H6: ='N TRIBUTARIO'!H250 -> 1405 | I6: ='N TRIBUTARIO'!I250 -> 0 | J6: , | K6: ='N TRIBUTARIO'!J250 -> EL CARMEN | L6: ='N TRIBUTARIO'!K250 -> SUR | M6: ='N TRIBUTARIO'!L250 -> LA UNION | N6: ='N TRIBUTARIO'!M250 -> 0 | O6: ='N TRIBUTARIO'!N250 -> 0 | P6: ='N TRIBUTARIO'!O250 -> 0 | Q6: ='N TRIBUTARIO'!P250 -> 0 | R6: ='N TRIBUTARIO'!Q250 -> 0 | ... AD6: ='N TRIBUTARIO'!AC250 -> 0
A7: ='N TRIBUTARIO'!A251 -> 0 | B7: ='N TRIBUTARIO'!B251 -> 14 | C7: ='N TRIBUTARIO'!C251 -> 10 | D7: ='N TRIBUTARIO'!D251 -> 79 | E7: ='N TRIBUTARIO'!E251 -> 001 | F7: ='N TRIBUTARIO'!F251 -> 0 | G7: ='N TRIBUTARIO'!G251 -> 250 | H7: ='N TRIBUTARIO'!H251 -> 1406 | I7: ='N TRIBUTARIO'!I251 -> 0 | J7: , | K7: ='N TRIBUTARIO'!J251 -> EL SAUCE | L7: ='N TRIBUTARIO'!K251 -> NORTE | M7: ='N TRIBUTARIO'!L251 -> LA UNION | N7: ='N TRIBUTARIO'!M251 -> 0 | O7: ='N TRIBUTARIO'!N251 -> 0 | P7: ='N TRIBUTARIO'!O251 -> 0 | Q7: ='N TRIBUTARIO'!P251 -> 1 | R7: ='N TRIBUTARIO'!Q251 -> 0 | ... AD7: ='N TRIBUTARIO'!AC251 -> 0
A8: ='N TRIBUTARIO'!A252 -> 0 | B8: ='N TRIBUTARIO'!B252 -> 14 | C8: ='N TRIBUTARIO'!C252 -> 10 | D8: ='N TRIBUTARIO'!D252 -> 79 | E8: ='N TRIBUTARIO'!E252 -> 001 | F8: ='N TRIBUTARIO'!F252 -> 0 | G8: ='N TRIBUTARIO'!G252 -> 251 | H8: ='N TRIBUTARIO'!H252 -> 1407 | I8: ='N TRIBUTARIO'!I252 -> 0 | J8: , | K8: ='N TRIBUTARIO'!J252 -> INTIPUCA | L8: ='N TRIBUTARIO'!K252 -> SUR | M8: ='N TRIBUTARIO'!L252 -> LA UNION | N8: ='N TRIBUTARIO'!M252 -> 0 | O8: ='N TRIBUTARIO'!N252 -> 0 | P8: ='N TRIBUTARIO'!O252 -> 0 | Q8: ='N TRIBUTARIO'!P252 -> 0 | R8: ='N TRIBUTARIO'!Q252 -> 0 | ... AD8: ='N TRIBUTARIO'!AC252 -> 0
A9: ='N TRIBUTARIO'!A253 -> 0 | B9: ='N TRIBUTARIO'!B253 -> 01 | C9: ='N TRIBUTARIO'!C253 -> 06 | D9: ='N TRIBUTARIO'!D253 -> 11 | E9: ='N TRIBUTARIO'!E253 -> 001 | F9: ='N TRIBUTARIO'!F253 -> 9 | G9: ='N TRIBUTARIO'!G253 -> 252 | H9: ='N TRIBUTARIO'!H253 -> 1408 | I9: ='N TRIBUTARIO'!I253 -> 14 | J9: , | K9: ='N TRIBUTARIO'!J253 -> LA UNION | L9: ='N TRIBUTARIO'!K253 -> SUR | M9: ='N TRIBUTARIO'!L253 -> LA UNION | N9: ='N TRIBUTARIO'!M253 -> 0 | O9: ='N TRIBUTARIO'!N253 -> 0 | P9: ='N TRIBUTARIO'!O253 -> 0 | Q9: ='N TRIBUTARIO'!P253 -> 0 | R9: ='N TRIBUTARIO'!Q253 -> 0 | ... AD9: ='N TRIBUTARIO'!AC253 -> 0
A10: ='N TRIBUTARIO'!A254 -> 0 | B10: ='N TRIBUTARIO'!B254 -> 14 | C10: ='N TRIBUTARIO'!C254 -> 10 | D10: ='N TRIBUTARIO'!D254 -> 79 | E10: ='N TRIBUTARIO'!E254 -> 001 | F10: ='N TRIBUTARIO'!F254 -> 0 | G10: ='N TRIBUTARIO'!G254 -> 253 | H10: ='N TRIBUTARIO'!H254 -> 1409 | I10: ='N TRIBUTARIO'!I254 -> 0 | J10: , | K10: ='N TRIBUTARIO'!J254 -> LISLIQUE | L10: ='N TRIBUTARIO'!K254 -> NORTE | M10: ='N TRIBUTARIO'!L254 -> LA UNION | N10: ='N TRIBUTARIO'!M254 -> 0 | O10: ='N TRIBUTARIO'!N254 -> 0 | P10: ='N TRIBUTARIO'!O254 -> 0 | Q10: ='N TRIBUTARIO'!P254 -> 1 | R10: ='N TRIBUTARIO'!Q254 -> 0 | ... AD10: ='N TRIBUTARIO'!AC254 -> 0
A11: ='N TRIBUTARIO'!A255 -> 0 | B11: ='N TRIBUTARIO'!B255 -> 17 | C11: ='N TRIBUTARIO'!C255 -> 06 | D11: ='N TRIBUTARIO'!D255 -> 16 | E11: ='N TRIBUTARIO'!E255 -> 001 | F11: ='N TRIBUTARIO'!F255 -> 9 | G11: ='N TRIBUTARIO'!G255 -> 254 | H11: ='N TRIBUTARIO'!H255 -> 1410 | I11: ='N TRIBUTARIO'!I255 -> 0 | J11: , | K11: ='N TRIBUTARIO'!J255 -> MEANGUERA DEL GOLFO | L11: ='N TRIBUTARIO'!K255 -> SUR | M11: ='N TRIBUTARIO'!L255 -> LA UNION | N11: ='N TRIBUTARIO'!M255 -> 0 | O11: ='N TRIBUTARIO'!N255 -> 0 | P11: ='N TRIBUTARIO'!O255 -> 0 | Q11: ='N TRIBUTARIO'!P255 -> 0 | R11: ='N TRIBUTARIO'!Q255 -> 0 | ... AD11: ='N TRIBUTARIO'!AC255 -> 0
A12: ='N TRIBUTARIO'!A256 -> 0 | B12: ='N TRIBUTARIO'!B256 -> 14 | C12: ='N TRIBUTARIO'!C256 -> 10 | D12: ='N TRIBUTARIO'!D256 -> 79 | E12: ='N TRIBUTARIO'!E256 -> 001 | F12: ='N TRIBUTARIO'!F256 -> 1 | G12: ='N TRIBUTARIO'!G256 -> 255 | H12: ='N TRIBUTARIO'!H256 -> 1411 | I12: ='N TRIBUTARIO'!I256 -> 0 | J12: , | K12: ='N TRIBUTARIO'!J256 -> NUEVA ESPARTA | L12: ='N TRIBUTARIO'!K256 -> NORTE | M12: ='N TRIBUTARIO'!L256 -> LA UNION | N12: ='N TRIBUTARIO'!M256 -> 0 | O12: ='N TRIBUTARIO'!N256 -> 0 | P12: ='N TRIBUTARIO'!O256 -> 0 | Q12: ='N TRIBUTARIO'!P256 -> 1 | R12: ='N TRIBUTARIO'!Q256 -> 0 | ... AD12: ='N TRIBUTARIO'!AC256 -> 0
A13: ='N TRIBUTARIO'!A257 -> 0 | B13: ='N TRIBUTARIO'!B257 -> 14 | C13: ='N TRIBUTARIO'!C257 -> 10 | D13: ='N TRIBUTARIO'!D257 -> 79 | E13: ='N TRIBUTARIO'!E257 -> 001 | F13: ='N TRIBUTARIO'!F257 -> 1 | G13: ='N TRIBUTARIO'!G257 -> 256 | H13: ='N TRIBUTARIO'!H257 -> 1412 | I13: ='N TRIBUTARIO'!I257 -> 0 | J13: , | K13: ='N TRIBUTARIO'!J257 -> PASAQUINA | L13: ='N TRIBUTARIO'!K257 -> NORTE | M13: ='N TRIBUTARIO'!L257 -> LA UNION | N13: ='N TRIBUTARIO'!M257 -> 0 | O13: ='N TRIBUTARIO'!N257 -> 0 | P13: ='N TRIBUTARIO'!O257 -> 0 | Q13: ='N TRIBUTARIO'!P257 -> 1 | R13: ='N TRIBUTARIO'!Q257 -> 0 | ... AD13: ='N TRIBUTARIO'!AC257 -> 0
... A19: ='N TRIBUTARIO'!A263 -> 0 | B19: ='N TRIBUTARIO'!B263 -> 14 | C19: ='N TRIBUTARIO'!C263 -> 10 | D19: ='N TRIBUTARIO'!D263 -> 79 | E19: ='N TRIBUTARIO'!E263 -> 001 | F19: ='N TRIBUTARIO'!F263 -> 1 | G19: ='N TRIBUTARIO'!G263 -> 262 | H19: ='N TRIBUTARIO'!H263 -> 1418 | I19: ='N TRIBUTARIO'!I263 -> 0 | J19: , | K19: ='N TRIBUTARIO'!J263 -> YUCUAIQUIN | L19: ='N TRIBUTARIO'!K263 -> SUR | M19: ='N TRIBUTARIO'!L263 -> LA UNION | N19: ='N TRIBUTARIO'!M263 -> 0 | O19: ='N TRIBUTARIO'!N263 -> 0 | P19: ='N TRIBUTARIO'!O263 -> 0 | Q19: ='N TRIBUTARIO'!P263 -> 0 | R19: ='N TRIBUTARIO'!Q263 -> 0 | ... AD19: ='N TRIBUTARIO'!AC263 -> 0
N20: =SUM(N2:N19) -> 0 | O20: =SUM(O2:O19) -> 0 | P20: =SUM(P2:P19) -> 0 | Q20: =SUM(Q2:Q19) -> 10 | R20: =SUM(R2:R19) -> 0 | S20: =SUM(S2:S19) -> 8 | T20: =SUM(T2:T19) -> 0
J21: =Q1 -> NORTE | K21: =CONCATENATE(K2,J2,K3,J3,K4,J4,K7,J7,K10,J10,K12,J12,K13,J13,K14,J14,K16,J16,K17) -> ANAMOROS, BOLIVAR, CONCEPCION DE ORIENTE, EL SAUCE, LISLIQUE, NUEVA ESPARTA, PASAQUINA, POLOROS, SAN JOSE, SANTA ROSA DE LIMA
J22: =S1 -> SUR | K22: =CONCATENATE(K5,J5,K6,J6,K8,J8,K9,J9,K11,J11,K15,J15,K18,J18,K19) -> CONCHAGUA, EL CARMEN, INTIPUCA, LA UNION, MEANGUERA DEL GOLFO, SAN ALEJO, YAYANTIQUE, YUCUAIQUIN

Sheet DEPT
B2: No. | C2: ='N TRIBUTARIO'!M1 -> CENTRO | D2: ='N TRIBUTARIO'!N1 -> COSTA | E2: ='N TRIBUTARIO'!O1 -> ESTE | F2: ='N TRIBUTARIO'!P1 -> NORTE | G2: ='N TRIBUTARIO'!Q1 -> OESTE | H2: ='N TRIBUTARIO'!R1 -> SUR | I2: TOTAL | K2: Area (km²) | L2: Poblacion | M2: Densidad (Hab/Km²) | N2: Distritos internos
B3: 1 | C3: ='1 ahu'!N14 -> 4 | D3: ='1 ahu'!O14 -> 0 | E3: ='1 ahu'!P14 -> 0 | F3: ='1 ahu'!Q14 -> 4 | G3: ='1 ahu'!R14 -> 0 | H3: ='1 ahu'!S14 -> 4 | I3: =SUM(C3:H3) -> 12 | J3: AHUACHAPÁN
B4: 2 | C4: ='2 sa'!N15 -> 1 | D4: ='2 sa'!O15 -> 0 | E4: ='2 sa'!P15 -> 2 | F4: ='2 sa'!Q15 -> 4 | G4: ='2 sa'!R15 -> 6 | H4: ='2 sa'!S15 -> 0 | I4: =SUM(C4:H4) -> 13 | J4: SANTA ANA
B5: 3 | C5: ='3 son '!N18 -> 5 | D5: ='3 son '!O18 -> 0 | E5: ='3 son '!P18 -> 6 | F5: ='3 son '!Q18 -> 4 | G5: ='3 son '!R18 -> 1 | H5: ='3 son '!S18 -> 0 | I5: =SUM(C5:H5) -> 16 | J5: SONSONATE
B6: 4 | C6: ='4 cha'!N35 -> 10 | D6: ='4 cha'!O35 -> 0 | E6: ='4 cha'!P35 -> 0 | F6: ='4 cha'!Q35 -> 3 | G6: ='4 cha'!R35 -> 0 | H6: ='4 cha'!S35 -> 20 | I6: =SUM(C6:H6) -> 33 | J6: CHALATENANGO
B7: 5 | C7: ='5 LL'!N24 -> 2 | D7: ='5 LL'!O24 -> 4 | E7: ='5 LL'!P24 -> 5 | F7: ='5 LL'!Q24 -> 4 | G7: ='5 LL'!R24 -> 5 | H7: ='5 LL'!S24 -> 2 | I7: =SUM(C7:H7) -> 22 | J7: LA LIBERTAD
B8: 6 | C8: ='6 ss'!N21 -> 5 | D8: ='6 ss'!O21 -> 0 | E8: ='6 ss'!P21 -> 4 | F8: ='6 ss'!Q21 -> 3 | G8: ='6 ss'!R21 -> 2 | H8: ='6 ss'!S21 -> 5 | I8: =SUM(C8:H8) -> 19 | J8: SAN SALVADOR
B9: 7 | C9: ='7 cus'!N18 -> 0 | D9: ='7 cus'!O18 -> 0 | E9: ='7 cus'!P18 -> 0 | F9: ='7 cus'!Q18 -> 6 | G9: ='7 cus'!R18 -> 0 | H9: ='7 cus'!S18 -> 10 | I9: =SUM(C9:H9) -> 16 | J9: CUSCATLÁN
B10: 8 | C10: ='8 lp'!N24 -> 12 | D10: ='8 lp'!O24 -> 0 | E10: ='8 lp'!P24 -> 3 | F10: ='8 lp'!Q24 -> 0 | G10: ='8 lp'!R24 -> 7 | H10: ='8 lp'!S24 -> 0 | I10: =SUM(C10:H10) -> 22 | J10: LA PAZ
B11: 9 | C11: ='9 cab'!N11 -> 0 | D11: ='9 cab'!O11 -> 0 | E11: ='9 cab'!P11 -> 5 | F11: ='9 cab'!Q11 -> 0 | G11: ='9 cab'!R11 -> 4 | H11: ='9 cab'!S11 -> 0 | I11: =SUM(C11:H11) -> 9 | J11: CABAÑAS
B12: 10 | C12: ='10 sv'!N15 -> 0 | D12: ='10 sv'!O15 -> 0 | E12: ='10 sv'!P15 -> 0 | F12: ='10 sv'!Q15 -> 7 | G12: ='10 sv'!R15 -> 0 | H12: ='10 sv'!S15 -> 6 | I12: =SUM(C12:H12) -> 13 | J12: SAN VICENTE
B13: 11 | C13: ='11 usu'!N25 -> 0 | D13: ='11 usu'!O25 -> 0 | E13: ='11 usu'!P25 -> 10 | F13: ='11 usu'!Q25 -> 9 | G13: ='11 usu'!R25 -> 4 | H13: ='11 usu'!S25 -> 0 | I13: =SUM(C13:H13) -> 23 | J13: USULUTAN
B14: 12 | C14: ='12 sm'!N22 -> 6 | D14: ='12 sm'!O22 -> 0 | E14: ='12 sm'!P22 -> 0 | F14: ='12 sm'!Q22 -> 8 | G14: ='12 sm'!R22 -> 6 | H14: ='12 sm'!S22 -> 0 | I14: =SUM(C14:H14) -> 20 | J14: SAN MIGUEL
B15: 13 | C15: ='13 mor'!N28 -> 0 | D15: ='13 mor'!O28 -> 0 | E15: ='13 mor'!P28 -> 0 | F15: ='13 mor'!Q28 -> 11 | G15: ='13 mor'!R28 -> 0 | H15: ='13 mor'!S28 -> 15 | I15: =SUM(C15:H15) -> 26 | J15: MORAZÁN
B16: 14 | C16: ='14 LU'!N20 -> 0 | D16: ='14 LU'!O20 -> 0 | E16: ='14 LU'!P20 -> 0 | F16: ='14 LU'!Q20 -> 10 | G16: ='14 LU'!R20 -> 0 | H16: ='14 LU'!S20 -> 8 | I16: =SUM(C16:H16) -> 18 | J16: LA UNION
C17: =SUM(C3:C16) -> 45 | D17: =SUM(D3:D16) -> 4 | E17: =SUM(E3:E16) -> 35 | F17: =SUM(F3:F16) -> 73 | G17: =SUM(G3:G16) -> 35 | H17: =SUM(H3:H16) -> 70 | I17: =SUM(I3:I16) -> 262
C18: =SUM(C17:H17) -> 262

Sheet 1 ahu
A1: CODIZONAL | B1: DIA | C1: MES | D1: AÑO | E1: SERIE | F1: CODIGO | G1: NUMERO | H1: CORRELATIVO | I1: # DE DEPARTAMENTO | K1: NOMBRE DE DISTRITO | L1: ZONA | M1: NOMBRE DEPARTAMENTO | N1: CENTRO | O1: COSTA | P1: ESTE | Q1: NORTE | R1: OESTE | S1: SUR | T1: NO DETERMINADO | W1: DISTCODIGOZONA | X1: NITDIST | Y1: NOMBRE DISTRITO ZONA | Z1: NIT DISTRITO NOMBRE ZONA | AA1: CODIGO NOMBRE ZONA | AB1: AREA (KM2) | AC1: POBLACION | AD1: DENSIDAD (HAB./KM2)
A2: ='N TRIBUTARIO'!A2 -> 1C | B2: ='N TRIBUTARIO'!B2 -> 01 | C2: ='N TRIBUTARIO'!C2 -> 06 | D2: ='N TRIBUTARIO'!D2 -> 11 | E2: ='N TRIBUTARIO'!E2 -> 001 | F2: ='N TRIBUTARIO'!F2 -> 0 | G2: ='N TRIBUTARIO'!G2 -> 1 | H2: ='N TRIBUTARIO'!H2 -> 0101 | I2: ='N TRIBUTARIO'!I2 -> 1 | J2: , | K2: ='N TRIBUTARIO'!J2 -> AHUACHAPAN | L2: ='N TRIBUTARIO'!K2 -> CENTRO | M2: ='N TRIBUTARIO'!L2 -> AHUACHAPAN | N2: ='N TRIBUTARIO'!M2 -> 1 | O2: ='N TRIBUTARIO'!N2 -> 0 | P2: ='N TRIBUTARIO'!O2 -> 0 | Q2: ='N TRIBUTARIO'!P2 -> 0 | R2: ='N TRIBUTARIO'!Q2 -> 0 | ... AD2: ='N TRIBUTARIO'!AC2 -> 474.82
A3: ='N TRIBUTARIO'!A3 -> 0 | B3: ='N TRIBUTARIO'!B3 -> 01 | C3: ='N TRIBUTARIO'!C3 -> 10 | D3: ='N TRIBUTARIO'!D3 -> 79 | E3: ='N TRIBUTARIO'!E3 -> 001 | F3: ='N TRIBUTARIO'!F3 -> 9 | G3: ='N TRIBUTARIO'!G3 -> 2 | H3: ='N TRIBUTARIO'!H3 -> 0102 | I3: ='N TRIBUTARIO'!I3 -> 0 | J3: , | K3: ='N TRIBUTARIO'!J3 -> APANECA | L3: ='N TRIBUTARIO'!K3 -> CENTRO | M3: ='N TRIBUTARIO'!L3 -> AHUACHAPAN | N3: ='N TRIBUTARIO'!M3 -> 1 | O3: ='N TRIBUTARIO'!N3 -> 0 | P3: ='N TRIBUTARIO'!O3 -> 0 | Q3: ='N TRIBUTARIO'!P3 -> 0 | R3: ='N TRIBUTARIO'!Q3 -> 0 | ... AD3: ='N TRIBUTARIO'!AC3 -> 0
A4: ='N TRIBUTARIO'!A4 -> N1 | B4: ='N TRIBUTARIO'!B4 -> 01 | C4: ='N TRIBUTARIO'!C4 -> 10 | D4: ='N TRIBUTARIO'!D4 -> 79 | E4: ='N TRIBUTARIO'!E4 -> 001 | F4: ='N TRIBUTARIO'!F4 -> 9 | G4: ='N TRIBUTARIO'!G4 -> 3 | H4: ='N TRIBUTARIO'!H4 -> 0103 | I4: ='N TRIBUTARIO'!I4 -> 0 | J4: , | K4: ='N TRIBUTARIO'!J4 -> ATIQUIZAYA | L4: ='N TRIBUTARIO'!K4 -> NORTE | M4: ='N TRIBUTARIO'!L4 -> AHUACHAPAN | N4: ='N TRIBUTARIO'!M4 -> 0 | O4: ='N TRIBUTARIO'!N4 -> 0 | P4: ='N TRIBUTARIO'!O4 -> 0 | Q4: ='N TRIBUTARIO'!P4 -> 1 | R4: ='N TRIBUTARIO'!Q4 -> 0 | ... AD4: ='N TRIBUTARIO'!AC4 -> 420.18
A5: ='N TRIBUTARIO'!A5 -> 0 | B5: ='N TRIBUTARIO'!B5 -> 01 | C5: ='N TRIBUTARIO'!C5 -> 10 | D5: ='N TRIBUTARIO'!D5 -> 79 | E5: ='N TRIBUTARIO'!E5 -> 001 | F5: ='N TRIBUTARIO'!F5 -> 9 | G5: ='N TRIBUTARIO'!G5 -> 4 | H5: ='N TRIBUTARIO'!H5 -> 0104 | I5: ='N TRIBUTARIO'!I5 -> 0 | J5: , | K5: ='N TRIBUTARIO'!J5 -> CONCEPCION DE ATACO | L5: ='N TRIBUTARIO'!K5 -> CENTRO | M5: ='N TRIBUTARIO'!L5 -> AHUACHAPAN | N5: ='N TRIBUTARIO'!M5 -> 1 | O5: ='N TRIBUTARIO'!N5 -> 0 | P5: ='N TRIBUTARIO'!O5 -> 0 | Q5: ='N TRIBUTARIO'!P5 -> 0 | R5: ='N TRIBUTARIO'!Q5 -> 0 | ... AD5: ='N TRIBUTARIO'!AC5 -> 0
A6: ='N TRIBUTARIO'!A6 -> 0 | B6: ='N TRIBUTARIO'!B6 -> 01 | C6: ='N TRIBUTARIO'!C6 -> 10 | D6: ='N TRIBUTARIO'!D6 -> 79 | E6: ='N TRIBUTARIO'!E6 -> 001 | F6: ='N TRIBUTARIO'!F6 -> 9 | G6: ='N TRIBUTARIO'!G6 -> 5 | H6: ='N TRIBUTARIO'!H6 -> 0105 | I6: ='N TRIBUTARIO'!I6 -> 0 | J6: , | K6: ='N TRIBUTARIO'!J6 -> EL REFUGIO | L6: ='N TRIBUTARIO'!K6 -> NORTE | M6: ='N TRIBUTARIO'!L6 -> AHUACHAPAN | N6: ='N TRIBUTARIO'!M6 -> 0 | O6: ='N TRIBUTARIO'!N6 -> 0 | P6: ='N TRIBUTARIO'!O6 -> 0 | Q6: ='N TRIBUTARIO'!P6 -> 1 | R6: ='N TRIBUTARIO'!Q6 -> 0 | ... AD6: ='N TRIBUTARIO'!AC6 -> 0
A7: ='N TRIBUTARIO'!A7 -> S1 | B7: ='N TRIBUTARIO'!B7 -> 01 | C7: ='N TRIBUTARIO'!C7 -> 10 | D7: ='N TRIBUTARIO'!D7 -> 79 | E7: ='N TRIBUTARIO'!E7 -> 001 | F7: ='N TRIBUTARIO'!F7 -> 9 | G7: ='N TRIBUTARIO'!G7 -> 6 | H7: ='N TRIBUTARIO'!H7 -> 0106 | I7: ='N TRIBUTARIO'!I7 -> 0 | J7: , | K7: ='N TRIBUTARIO'!J7 -> GUAYMANGO | L7: ='N TRIBUTARIO'!K7 -> SUR | M7: ='N TRIBUTARIO'!L7 -> AHUACHAPAN | N7: ='N TRIBUTARIO'!M7 -> 0 | O7: ='N TRIBUTARIO'!N7 -> 0 | P7: ='N TRIBUTARIO'!O7 -> 0 | Q7: ='N TRIBUTARIO'!P7 -> 0 | R7: ='N TRIBUTARIO'!Q7 -> 0 | ... AD7: ='N TRIBUTARIO'!AC7 -> 173.24
A8: ='N TRIBUTARIO'!A8 -> 0 | B8: ='N TRIBUTARIO'!B8 -> 01 | C8: ='N TRIBUTARIO'!C8 -> 10 | D8: ='N TRIBUTARIO'!D8 -> 79 | E8: ='N TRIBUTARIO'!E8 -> 001 | F8: ='N TRIBUTARIO'!F8 -> 9 | G8: ='N TRIBUTARIO'!G8 -> 7 | H8: ='N TRIBUTARIO'!H8 -> 0107 | I8: ='N TRIBUTARIO'!I8 -> 0 | J8: , | K8: ='N TRIBUTARIO'!J8 -> JUJUTLA | L8: ='N TRIBUTARIO'!K8 -> SUR | M8: ='N TRIBUTARIO'!L8 -> AHUACHAPAN | N8: ='N TRIBUTARIO'!M8 -> 0 | O8: ='N TRIBUTARIO'!N8 -> 0 | P8: ='N TRIBUTARIO'!O8 -> 0 | Q8: ='N TRIBUTARIO'!P8 -> 0 | R8: ='N TRIBUTARIO'!Q8 -> 0 | ... AD8: ='N TRIBUTARIO'!AC8 -> 0
A9: ='N TRIBUTARIO'!A9 -> 0 | B9: ='N TRIBUTARIO'!B9 -> 01 | C9: ='N TRIBUTARIO'!C9 -> 10 | D9: ='N TRIBUTARIO'!D9 -> 79 | E9: ='N TRIBUTARIO'!E9 -> 001 | F9: ='N TRIBUTARIO'!F9 -> 2 | G9: ='N TRIBUTARIO'!G9 -> 8 | H9: ='N TRIBUTARIO'!H9 -> 0108 | I9: ='N TRIBUTARIO'!I9 -> 0 | J9: , | K9: ='N TRIBUTARIO'!J9 -> SAN FRANCISCO MENENDEZ | L9: ='N TRIBUTARIO'!K9 -> SUR | M9: ='N TRIBUTARIO'!L9 -> AHUACHAPAN | N9: ='N TRIBUTARIO'!M9 -> 0 | O9: ='N TRIBUTARIO'!N9 -> 0 | P9: ='N TRIBUTARIO'!O9 -> 0 | Q9: ='N TRIBUTARIO'!P9 -> 0 | R9: ='N TRIBUTARIO'!Q9 -> 0 | ... AD9: ='N TRIBUTARIO'!AC9 -> 0
A10: ='N TRIBUTARIO'!A10 -> 0 | B10: ='N TRIBUTARIO'!B10 -> 01 | C10: ='N TRIBUTARIO'!C10 -> 10 | D10: ='N TRIBUTARIO'!D10 -> 79 | E10: ='N TRIBUTARIO'!E10 -> 001 | F10: ='N TRIBUTARIO'!F10 -> 9 | G10: ='N TRIBUTARIO'!G10 -> 9 | H10: ='N TRIBUTARIO'!H10 -> 0109 | I10: ='N TRIBUTARIO'!I10 -> 0 | J10: , | K10: ='N TRIBUTARIO'!J10 -> SAN LORENZO | L10: ='N TRIBUTARIO'!K10 -> NORTE | M10: ='N TRIBUTARIO'!L10 -> AHUACHAPAN | N10: ='N TRIBUTARIO'!M10 -> 0 | O10: ='N TRIBUTARIO'!N10 -> 0 | P10: ='N TRIBUTARIO'!O10 -> 0 | Q10: ='N TRIBUTARIO'!P10 -> 1 | R10: ='N TRIBUTARIO'!Q10 -> 0 | ... AD10: ='N TRIBUTARIO'!AC10 -> 0
A11: ='N TRIBUTARIO'!A11 -> 0 | B11: ='N TRIBUTARIO'!B11 -> 01 | C11: ='N TRIBUTARIO'!C11 -> 10 | D11: ='N TRIBUTARIO'!D11 -> 79 | E11: ='N TRIBUTARIO'!E11 -> 001 | F11: ='N TRIBUTARIO'!F11 -> 0 | G11: ='N TRIBUTARIO'!G11 -> 10 | H11: ='N TRIBUTARIO'!H11 -> 0110 | I11: ='N TRIBUTARIO'!I11 -> 0 | J11: , | K11: ='N TRIBUTARIO'!J11 -> SAN PEDRO PUXTLA | L11: ='N TRIBUTARIO'!K11 -> SUR | M11: ='N TRIBUTARIO'!L11 -> AHUACHAPAN | N11: ='N TRIBUTARIO'!M11 -> 0 | O11: ='N TRIBUTARIO'!N11 -> 0 | P11: ='N TRIBUTARIO'!O11 -> 0 | Q11: ='N TRIBUTARIO'!P11 -> 0 | R11: ='N TRIBUTARIO'!Q11 -> 0 | ... AD11: ='N TRIBUTARIO'!AC11 -> 0
A12: ='N TRIBUTARIO'!A12 -> 0 | B12: ='N TRIBUTARIO'!B12 -> 01 | C12: ='N TRIBUTARIO'!C12 -> 10 | D12: ='N TRIBUTARIO'!D12 -> 79 | E12: ='N TRIBUTARIO'!E12 -> 001 | F12: ='N TRIBUTARIO'!F12 -> 0 | G12: ='N TRIBUTARIO'!G12 -> 11 | H12: ='N TRIBUTARIO'!H12 -> 0111 | I12: ='N TRIBUTARIO'!I12 -> 0 | J12: , | K12: ='N TRIBUTARIO'!J12 -> TACUBA | L12: ='N TRIBUTARIO'!K12 -> CENTRO | M12: ='N TRIBUTARIO'!L12 -> AHUACHAPAN | N12: ='N TRIBUTARIO'!M12 -> 1 | O12: ='N TRIBUTARIO'!N12 -> 0 | P12: ='N TRIBUTARIO'!O12 -> 0 | Q12: ='N TRIBUTARIO'!P12 -> 0 | R12: ='N TRIBUTARIO'!Q12 -> 0 | ... AD12: ='N TRIBUTARIO'!AC12 -> 0
A13: ='N TRIBUTARIO'!A13 -> 0 | B13: ='N TRIBUTARIO'!B13 -> 01 | C13: ='N TRIBUTARIO'!C13 -> 10 | D13: ='N TRIBUTARIO'!D13 -> 79 | E13: ='N TRIBUTARIO'!E13 -> 001 | F13: ='N TRIBUTARIO'!F13 -> 0 | G13: ='N TRIBUTARIO'!G13 -> 12 | H13: ='N TRIBUTARIO'!H13 -> 0112 | I13: ='N TRIBUTARIO'!I13 -> 0 | J13: , | K13: ='N TRIBUTARIO'!J13 -> TURIN | L13: ='N TRIBUTARIO'!K13 -> NORTE | M13: ='N TRIBUTARIO'!L13 -> AHUACHAPAN | N13: ='N TRIBUTARIO'!M13 -> 0 | O13: ='N TRIBUTARIO'!N13 -> 0 | P13: ='N TRIBUTARIO'!O13 -> 0 | Q13: ='N TRIBUTARIO'!P13 -> 1 | R13: ='N TRIBUTARIO'!Q13 -> 0 | ... AD13: ='N TRIBUTARIO'!AC13 -> 0
N14: =SUM(N2:N13) -> 4 | O14: =SUM(O2:O13) -> 0 | P14: =SUM(P2:P13) -> 0 | Q14: =SUM(Q2:Q13) -> 4 | R14: =SUM(R2:R13) -> 0 | S14: =SUM(S2:S13) -> 4 | T14: =SUM(T2:T13) -> 0
I16: =N1 -> CENTRO | K16: =CONCATENATE(K2,J2,K3,J3,K5,J5,K12) -> AHUACHAPAN, APANECA, CONCEPCION DE ATACO, TACUBA
I17: =Q1 -> NORTE | K17: =CONCATENATE(K4,J4,K6,J6,K10,J10,K13) -> ATIQUIZAYA, EL REFUGIO, SAN LORENZO, TURIN
I18: =S1 -> SUR | K18: =CONCATENATE(K7,J7,K8,J8,K9,J9,K11,J1) -> GUAYMANGO, JUJUTLA, SAN FRANCISCO MENENDEZ, SAN PEDRO PUXTLA

Sheet 2 sa
A1: CODIZONAL | B1: DIA | C1: MES | D1: AÑO | E1: SERIE | F1: CODIGO | G1: NUMERO | H1: CORRELATIVO | I1: # DE DEPARTAMENTO | K1: NOMBRE DE DISTRITO | L1: ZONA | M1: NOMBRE DEPARTAMENTO | N1: CENTRO | O1: COSTA | P1: ESTE | Q1: NORTE | R1: OESTE | S1: SUR | T1: NO DETERMINADO | W1: DISTCODIGOZONA | X1: NITDIST | Y1: NOMBRE DISTRITO ZONA | Z1: NIT DISTRITO NOMBRE ZONA | AA1: CODIGO NOMBRE ZONA | AB1: AREA (KM2) | AC1: POBLACION | AD1: DENSIDAD (HAB./KM2)
A2: ='N TRIBUTARIO'!A14 -> O1 | B2: ='N TRIBUTARIO'!B14 -> 01 | C2: ='N TRIBUTARIO'!C14 -> 10 | D2: ='N TRIBUTARIO'!D14 -> 79 | E2: ='N TRIBUTARIO'!E14 -> 001 | F2: ='N TRIBUTARIO'!F14 -> 9 | G2: ='N TRIBUTARIO'!G14 -> 13 | H2: ='N TRIBUTARIO'!H14 -> 0201 | I2: ='N TRIBUTARIO'!I14 -> 0 | J2: , | K2: ='N TRIBUTARIO'!J14 -> CANDELARIA DE LA FRONTERA | L2: ='N TRIBUTARIO'!K14 -> OESTE | M2: ='N TRIBUTARIO'!L14 -> SANTA ANA | N2: ='N TRIBUTARIO'!M14 -> 0 | O2: ='N TRIBUTARIO'!N14 -> 0 | P2: ='N TRIBUTARIO'!O14 -> 0 | Q2: ='N TRIBUTARIO'!P14 -> 0 | R2: ='N TRIBUTARIO'!Q14 -> 1 | ... AD2: ='N TRIBUTARIO'!AC14 -> 384.12
A3: ='N TRIBUTARIO'!A15 -> E1 | B3: ='N TRIBUTARIO'!B15 -> 01 | C3: ='N TRIBUTARIO'!C15 -> 06 | D3: ='N TRIBUTARIO'!D15 -> 11 | E3: ='N TRIBUTARIO'!E15 -> 001 | F3: ='N TRIBUTARIO'!F15 -> 2 | G3: ='N TRIBUTARIO'!G15 -> 14 | H3: ='N TRIBUTARIO'!H15 -> 0202 | I3: ='N TRIBUTARIO'!I15 -> 0 | J3: , | K3: ='N TRIBUTARIO'!J15 -> COATEPEQUE | L3: ='N TRIBUTARIO'!K15 -> ESTE | M3: ='N TRIBUTARIO'!L15 -> SANTA ANA | N3: ='N TRIBUTARIO'!M15 -> 0 | O3: ='N TRIBUTARIO'!N15 -> 0 | P3: ='N TRIBUTARIO'!O15 -> 1 | Q3: ='N TRIBUTARIO'!P15 -> 0 | R3: ='N TRIBUTARIO'!Q15 -> 0 | ... AD3: ='N TRIBUTARIO'!AC15 -> 293.48
A4: ='N TRIBUTARIO'!A16 -> 0 | B4: ='N TRIBUTARIO'!B16 -> 01 | C4: ='N TRIBUTARIO'!C16 -> 06 | D4: ='N TRIBUTARIO'!D16 -> 11 | E4: ='N TRIBUTARIO'!E16 -> 001 | F4: ='N TRIBUTARIO'!F16 -> 2 | G4: ='N TRIBUTARIO'!G16 -> 15 | H4: ='N TRIBUTARIO'!H16 -> 0203 | I4: ='N TRIBUTARIO'!I16 -> 0 | J4: , | K4: ='N TRIBUTARIO'!J16 -> CHALCHUAPA | L4: ='N TRIBUTARIO'!K16 -> OESTE | M4: ='N TRIBUTARIO'!L16 -> SANTA ANA | N4: ='N TRIBUTARIO'!M16 -> 0 | O4: ='N TRIBUTARIO'!N16 -> 0 | P4: ='N TRIBUTARIO'!O16 -> 0 | Q4: ='N TRIBUTARIO'!P16 -> 0 | R4: ='N TRIBUTARIO'!Q16 -> 1 | ... AD4: ='N TRIBUTARIO'!AC16 -> 0
A5: ='N TRIBUTARIO'!A17 -> 0 | B5: ='N TRIBUTARIO'!B17 -> 02 | C5: ='N TRIBUTARIO'!C17 -> 10 | D5: ='N TRIBUTARIO'!D17 -> 79 | E5: ='N TRIBUTARIO'!E17 -> 001 | F5: ='N TRIBUTARIO'!F17 -> 9 | G5: ='N TRIBUTARIO'!G17 -> 16 | H5: ='N TRIBUTARIO'!H17 -> 0204 | I5: ='N TRIBUTARIO'!I17 -> 0 | J5: , | K5: ='N TRIBUTARIO'!J17 -> EL CONGO | L5: ='N TRIBUTARIO'!K17 -> ESTE | M5: ='N TRIBUTARIO'!L17 -> SANTA ANA | N5: ='N TRIBUTARIO'!M17 -> 0 | O5: ='N TRIBUTARIO'!N17 -> 0 | P5: ='N TRIBUTARIO'!O17 -> 1 | Q5: ='N TRIBUTARIO'!P17 -> 0 | R5: ='N TRIBUTARIO'!Q17 -> 0 | ... AD5: ='N TRIBUTARIO'!AC17 -> 0
A6: ='N TRIBUTARIO'!A18 -> 0 | B6: ='N TRIBUTARIO'!B18 -> 02 | C6: ='N TRIBUTARIO'!C18 -> 10 | D6: ='N TRIBUTARIO'!D18 -> 79 | E6: ='N TRIBUTARIO'!E18 -> 001 | F6: ='N TRIBUTARIO'!F18 -> 9 | G6: ='N TRIBUTARIO'!G18 -> 17 | H6: ='N TRIBUTARIO'!H18 -> 0205 | I6: ='N TRIBUTARIO'!I18 -> 0 | J6: , | K6: ='N TRIBUTARIO'!J18 -> EL PORVENIR | L6: ='N TRIBUTARIO'!K18 -> OESTE | M6: ='N TRIBUTARIO'!L18 -> SANTA ANA | N6: ='N TRIBUTARIO'!M18 -> 0 | O6: ='N TRIBUTARIO'!N18 -> 0 | P6: ='N TRIBUTARIO'!O18 -> 0 | Q6: ='N TRIBUTARIO'!P18 -> 0 | R6: ='N TRIBUTARIO'!Q18 -> 1 | ... AD6: ='N TRIBUTARIO'!AC18 -> 0
A7: ='N TRIBUTARIO'!A19 -> N1 | B7: ='N TRIBUTARIO'!B19 -> 02 | C7: ='N TRIBUTARIO'!C19 -> 10 | D7: ='N TRIBUTARIO'!D19 -> 79 | E7: ='N TRIBUTARIO'!E19 -> 001 | F7: ='N TRIBUTARIO'!F19 -> 9 | G7: ='N TRIBUTARIO'!G19 -> 18 | H7: ='N TRIBUTARIO'!H19 -> 0206 | I7: ='N TRIBUTARIO'!I19 -> 0 | J7: , | K7: ='N TRIBUTARIO'!J19 -> MASAHUAT | L7: ='N TRIBUTARIO'!K19 -> NORTE | M7: ='N TRIBUTARIO'!L19 -> SANTA ANA | N7: ='N TRIBUTARIO'!M19 -> 0 | O7: ='N TRIBUTARIO'!N19 -> 0 | P7: ='N TRIBUTARIO'!O19 -> 0 | Q7: ='N TRIBUTARIO'!P19 -> 1 | R7: ='N TRIBUTARIO'!Q19 -> 0 | ... AD7: ='N TRIBUTARIO'!AC19 -> 95.2
A8: ='N TRIBUTARIO'!A20 -> 0 | B8: ='N TRIBUTARIO'!B20 -> 01 | C8: ='N TRIBUTARIO'!C20 -> 06 | D8: ='N TRIBUTARIO'!D20 -> 11 | E8: ='N TRIBUTARIO'!E20 -> 002 | F8: ='N TRIBUTARIO'!F20 -> 4 | G8: ='N TRIBUTARIO'!G20 -> 19 | H8: ='N TRIBUTARIO'!H20 -> 0207 | I8: ='N TRIBUTARIO'!I20 -> 0 | J8: , | K8: ='N TRIBUTARIO'!J20 -> METAPAN | L8: ='N TRIBUTARIO'!K20 -> NORTE | M8: ='N TRIBUTARIO'!L20 -> SANTA ANA | N8: ='N TRIBUTARIO'!M20 -> 0 | O8: ='N TRIBUTARIO'!N20 -> 0 | P8: ='N TRIBUTARIO'!O20 -> 0 | Q8: ='N TRIBUTARIO'!P20 -> 1 | R8: ='N TRIBUTARIO'!Q20 -> 0 | ... AD8: ='N TRIBUTARIO'!AC20 -> 0
A9: ='N TRIBUTARIO'!A21 -> 0 | B9: ='N TRIBUTARIO'!B21 -> 02 | C9: ='N TRIBUTARIO'!C21 -> 10 | D9: ='N TRIBUTARIO'!D21 -> 79 | E9: ='N TRIBUTARIO'!E21 -> 001 | F9: ='N TRIBUTARIO'!F21 -> 9 | G9: ='N TRIBUTARIO'!G21 -> 20 | H9: ='N TRIBUTARIO'!H21 -> 0208 | I9: ='N TRIBUTARIO'!I21 -> 0 | J9: , | K9: ='N TRIBUTARIO'!J21 -> SAN ANTONIO PAJONAL | L9: ='N TRIBUTARIO'!K21 -> OESTE | M9: ='N TRIBUTARIO'!L21 -> SANTA ANA | N9: ='N TRIBUTARIO'!M21 -> 0 | O9: ='N TRIBUTARIO'!N21 -> 0 | P9: ='N TRIBUTARIO'!O21 -> 0 | Q9: ='N TRIBUTARIO'!P21 -> 0 | R9: ='N TRIBUTARIO'!Q21 -> 1 | ... AD9: ='N TRIBUTARIO'!AC21 -> 0
